Workbook

Sheet README
A1: VP per-renewal unit economics (round 2, r2-economics-renewal, 2026-10-17)
A2: Inputs: mode values, editable (yellow). Calc: LIVE FORMULAS evaluating the chain at those values (a deterministic 'mode case').
A3: The mode case is NOT the Monte Carlo median. Decision numbers are in MC_results (values from renewal_model.py, seed 20261017, n=20,000).
A4: Pricing_grid, Buyers, MDE and Sensitivity are VALUES copied from the CSVs written by renewal_model.py; Expansion, TRAI_check and Incumbents from expansion_sizing.py; IRDAI_extracts from extract_irdai_handbook.py.
A5: Per due policy unless labelled 'per 1,000 due'. INR. FX not used (all inputs are INR).
A6: Assumption-heavy: AI/human outcome parity, persuasion, baseline renewal rates and desk productivity are NOT measured. The interviews must measure them.
A7: Source tags: [prim] primary, [comp] computed from IRDAI Handbook 2024-25, [sec] secondary, [vend] vendor claim, [asm] assumption.

Sheet Inputs
A1: parameter | B1: description | C1: 2W_motor | D1: 4W_motor | E1: health | F1: life_yr2plus | G1: low-high range (MC) | H1: source tag
A2: P | B2: premium per renewal, INR | C2: 1500 | D2: 11000 | E2: 17000 | F2: 30000 | G2: 2W_motor: 714-3000; 4W_motor: 5000-25000; health: 9000-30000; life_yr2plus: 15000-75000 | H2: see renewal_model.py comments
A3: c | B3: commission share of premium | C3: 0.15 | D3: 0.18 | E3: 0.15 | F3: 0.05 | G3: 2W_motor: 0.08-0.25; 4W_motor: 0.1-0.28; health: 0.1-0.2; life_yr2plus: 0.03-0.075 | H3: see renewal_model.py comments
A4: b0 | B4: renewal rate with no calling | C4: 0.45 | D4: 0.6 | E4: 0.84 | F4: 0.8 | G4: 2W_motor: 0.3-0.6; 4W_motor: 0.45-0.75; health: 0.75-0.92; life_yr2plus: 0.7-0.9 | H4: see renewal_model.py comments
A5: s_pre | B5: share of baseline renewers who renew before the first call | C5: 0.25 | D5: 0.2 | E5: 0.3 | F5: 0.3 | G5: 2W_motor: 0.1-0.4; 4W_motor: 0.1-0.35; health: 0.15-0.45; life_yr2plus: 0.15-0.45 | H5: see renewal_model.py comments
A6: covH | B6: share of due list the human desk works | C6: 0.3 | D6: 0.8 | E6: 0.8 | F6: 0.8 | G6: 2W_motor: 0.1-0.6; 4W_motor: 0.5-1.0; health: 0.5-1.0; life_yr2plus: 0.5-1.0 | H6: see renewal_model.py comments
A7: persH | B7: P(saved | reached by human, would lapse) | C7: 0.25 | D7: 0.25 | E7: 0.2 | F7: 0.2 | G7: 2W_motor: 0.1-0.4; 4W_motor: 0.1-0.4; health: 0.08-0.35; life_yr2plus: 0.08-0.35 | H7: see renewal_model.py comments
A8: m_rpc | B8: minutes per right-party conversation | C8: 1.6 | D8: 2.5 | E8: 2 | F8: 2.5 | G8: 2W_motor: 1.0-2.5; 4W_motor: 1.5-4.0; health: 1.2-3.0; life_yr2plus: 1.5-3.5 | H8: see renewal_model.py comments
A9: r_future | B9: annual retention after a save (3-yr LTV) | C9: 0.55 | D9: 0.65 | E9: 0.87 | F9: 0.9 | G9: 2W_motor: 0.4-0.7; 4W_motor: 0.5-0.8; health: 0.8-0.92; life_yr2plus: 0.85-0.95 | H9: see renewal_model.py comments
A10: trough | B10: trough month / mean month due list | C10: 0.8 | D10: 0.8 | E10: 0.92 | F10: 0.7 | G10: 2W_motor: 0.7-0.9; 4W_motor: 0.7-0.9; health: 0.85-0.97; life_yr2plus: 0.55-0.85 | H10: see renewal_model.py comments
A12: common parameter | B12: description | C12: value | G12: low-high range (MC) | H12: source tag
A13: p_ans | B13: P(answered) per attempt [vend anchor Callyzer 46-48%] | C13: 0.42 | G13: 0.3-0.55
A14: q_rpc | B14: P(right party | answered) [asm] | C14: 0.88 | G14: 0.75-0.95
A15: r_max | B15: share reachable at all [asm] | C15: 0.88 | G15: 0.75-0.95
A16: f1600 | B16: pickup multiplier for AI on 1600xx [asm] | C16: 0.9 | G16: 0.7-1.05
A17: parity | B17: AI persuasion / human persuasion [asm] | C17: 0.8 | G17: 0.5-1.05
A18: m_nr | B18: minutes, answered wrong-party/not-now call [asm] | C18: 0.4 | G18: 0.2-0.8
A19: short | B19: RPC minutes for would-renew-anyway / m_rpc [asm] | C19: 0.6 | G19: 0.4-0.8
A20: wa | B20: WhatsApp utility messages per due policy [asm] | C20: 2 | G20: 1.0-3.0
A21: c_att | B21: INR per unanswered attempt [asm] | C21: 0.03 | G21: 0.0-0.15
A22: esc | B22: share of RPCs escalated to a human [asm] | C22: 0.12 | G22: 0.05-0.25
A23: m_esc | B23: human minutes per escalation [asm] | C23: 3.5 | G23: 2.0-6.0
A24: h | B24: INR per escalation minute [l2v 6-9] | C24: 6.3 | G24: 5.5-9.0
... A29: add1600 | B29: INR/min 1600-series adder [asm; quotes pending] | C29: 0.1 | G29: 0.0-0.4
A30: K_AI | B30: AI attempts per contact (mode of design range 3-6) | C30: 4
A31: K_H | B31: human attempts per worked contact [asm] | C31: 2
A32: cogs_launch | B32: INR/min managed COGS at 100k min/month, MC p50 [l2v] | C32: 5.88
A33: cogs_scale | B33: INR/min managed COGS at 1M min/month, MC p50 [l2] | C33: 3.06
A34: wa_price | B34: INR per WhatsApp utility template [prim, Meta rate card 2026-10-01] | C34: 0.115
A35: holdout | B35: share of due list held out [design] | C35: 0.1
A36: discount | B36: annual discount rate for LTV [asm] | C36: 0.12
A37: gm_target | B37: VP gross-margin target for the fee floor | C37: 0.4
A38: talk_min_per_seat_month | B38: l2v basis 200 talk-min/day x 24 days | C38: 4800
A40: fee_per_renewal | B40: fee per renewal collected (concept-test card) | C40: 20 | D40: 50 | E40: 15 | F40: 15

Sheet Calc
A1: step | B1: formula meaning | C1: 2W_motor | D1: 4W_motor | E1: health | F1: life_yr2plus
A2: W | B2: would-lapse share = 1 - b0 | C2: =1-Inputs!C4 -> 0.55 | D2: =1-Inputs!D4 -> 0.4 | E2: =1-Inputs!E4 -> 0.16 | F2: =1-Inputs!F4 -> 0.2
A3: called | B3: share unrenewed at first call = 1 - b0*s_pre | C3: =1-Inputs!C4*Inputs!C5 -> 0.8875 | D3: =1-Inputs!D4*Inputs!D5 -> 0.88 | E3: =1-Inputs!E4*Inputs!E5 -> 0.748 | F3: =1-Inputs!F4*Inputs!F5 -> 0.76
A4: share_wl | B4: would-lapse share of the called pool | C4: =C2/C3 -> 0.61971831 | D4: =D2/D3 -> 0.45454545 | E4: =E2/E3 -> 0.21390374 | F4: =F2/F3 -> 0.26315789
A5: m_mix | B5: RPC minutes, mixed pool | C5: =C4*Inputs!C8+(1-C4)*Inputs!C8*Inputs!$C$19 -> 1.3566197 | D5: =D4*Inputs!D8+(1-D4)*Inputs!D8*Inputs!$C$19 -> 1.9545455 | E5: =E4*Inputs!E8+(1-E4)*Inputs!E8*Inputs!$C$19 -> 1.371123 | F5: =F4*Inputs!F8+(1-F4)*Inputs!F8*Inputs!$C$19 -> 1.7631579
A6: p_ai | B6: AI answer prob per attempt = p_ans*f1600 (clipped) | C6: =MIN(0.95,MAX(0.01,Inputs!$C$13*Inputs!$C$16)) -> 0.378 | D6: =MIN(0.95,MAX(0.01,Inputs!$C$13*Inputs!$C$16)) -> 0.378 | E6: =MIN(0.95,MAX(0.01,Inputs!$C$13*Inputs!$C$16)) -> 0.378 | F6: =MIN(0.95,MAX(0.01,Inputs!$C$13*Inputs!$C$16)) -> 0.378
A7: a_ai | B7: AI RPC prob per attempt | C7: =C6*Inputs!$C$14 -> 0.33264 | D7: =D6*Inputs!$C$14 -> 0.33264 | E7: =E6*Inputs!$C$14 -> 0.33264 | F7: =F6*Inputs!$C$14 -> 0.33264
A8: hit_ai | B8: 1-(1-a)^K_AI | C8: =1-(1-C7)^Inputs!$C$30 -> 0.80164612 | D8: =1-(1-D7)^Inputs!$C$30 -> 0.80164612 | E8: =1-(1-E7)^Inputs!$C$30 -> 0.80164612 | F8: =1-(1-F7)^Inputs!$C$30 -> 0.80164612
A9: reach_ai | B9: AI right-party reach = r_max*hit | C9: =Inputs!$C$15*C8 -> 0.70544859 | D9: =Inputs!$C$15*D8 -> 0.70544859 | E9: =Inputs!$C$15*E8 -> 0.70544859 | F9: =Inputs!$C$15*F8 -> 0.70544859
A10: eatt_ai | B10: expected attempts per reachable contact = hit/a | C10: =C8/C7 -> 2.4099511 | D10: =D8/D7 -> 2.4099511 | E10: =E8/E7 -> 2.4099511 | F10: =F8/F7 -> 2.4099511
A11: att_ai | B11: attempts per called contact | C11: =Inputs!$C$15*C10+(1-Inputs!$C$15)*Inputs!$C$30 -> 2.6007569 | D11: =Inputs!$C$15*D10+(1-Inputs!$C$15)*Inputs!$C$30 -> 2.6007569 | E11: =Inputs!$C$15*E10+(1-Inputs!$C$15)*Inputs!$C$30 -> 2.6007569 | F11: =Inputs!$C$15*F10+(1-Inputs!$C$15)*Inputs!$C$30 -> 2.6007569
A12: answered_ai | B12: answered calls per called contact | C12: =Inputs!$C$15*C6*C10 -> 0.80164612 | D12: =Inputs!$C$15*D6*D10 -> 0.80164612 | E12: =Inputs!$C$15*E6*E10 -> 0.80164612 | F12: =Inputs!$C$15*F6*F10 -> 0.80164612
A13: nonrpc_ai | B13: answered, not right party | C13: =C12-C9 -> 0.096197535 | D13: =D12-D9 -> 0.096197535 | E13: =E12-E9 -> 0.096197535 | F13: =F12-F9 -> 0.096197535
A14: unans_ai | B14: unanswered attempts per called contact | C14: =C11-C12 -> 1.7991108 | D14: =D11-D12 -> 1.7991108 | E14: =E11-E12 -> 1.7991108 | F14: =F11-F12 -> 1.7991108
A15: d_ai | B15: incremental renewals per due vs no calling | C15: =C2*C9*MIN(1,Inputs!C7*Inputs!$C$17) -> 0.077599345 | D15: =D2*D9*MIN(1,Inputs!D7*Inputs!$C$17) -> 0.056435887 | E15: =E2*E9*MIN(1,Inputs!E7*Inputs!$C$17) -> 0.018059484 | F15: =F2*F9*MIN(1,Inputs!F7*Inputs!$C$17) -> 0.022574355
A16: min_ai | B16: AI connected minutes per worked due | C16: =C3*(C9*C5+C13*Inputs!$C$18)+C15*Inputs!$C$26 -> 1.0387089 | D16: =D3*(D9*D5+D13*Inputs!$C$18)+D15*Inputs!$C$26 -> 1.3601049 | E16: =E3*(E9*E5+E13*Inputs!$C$18)+E15*Inputs!$C$26 -> 0.78840934 | F16: =F3*(F9*F5+F13*Inputs!$C$18)+F15*Inputs!$C$26 -> 1.0196939
A17: a_h | B17: human RPC prob per attempt | C17: =Inputs!$C$13*Inputs!$C$14 -> 0.3696 | D17: =Inputs!$C$13*Inputs!$C$14 -> 0.3696 | E17: =Inputs!$C$13*Inputs!$C$14 -> 0.3696 | F17: =Inputs!$C$13*Inputs!$C$14 -> 0.3696
A18: hit_h | B18: 1-(1-a_h)^K_H | C18: =1-(1-C17)^Inputs!$C$31 -> 0.60259584 | D18: =1-(1-D17)^Inputs!$C$31 -> 0.60259584 | E18: =1-(1-E17)^Inputs!$C$31 -> 0.60259584 | F18: =1-(1-F17)^Inputs!$C$31 -> 0.60259584
A19: reach_h | B19: human reach | C19: =Inputs!$C$15*C18 -> 0.53028434 | D19: =Inputs!$C$15*D18 -> 0.53028434 | E19: =Inputs!$C$15*E18 -> 0.53028434 | F19: =Inputs!$C$15*F18 -> 0.53028434
A20: answered_h | B20: human answered calls per worked contact | C20: =Inputs!$C$15*Inputs!$C$13*C18/C17 -> 0.60259584 | D20: =Inputs!$C$15*Inputs!$C$13*D18/D17 -> 0.60259584 | E20: =Inputs!$C$15*Inputs!$C$13*E18/E17 -> 0.60259584 | F20: =Inputs!$C$15*Inputs!$C$13*F18/F17 -> 0.60259584
A21: d_h | B21: human incremental renewals per due | C21: =C2*Inputs!C6*C19*Inputs!C7 -> 0.021874229 | D21: =D2*Inputs!D6*D19*Inputs!D7 -> 0.042422747 | E21: =E2*Inputs!E6*E19*Inputs!E7 -> 0.013575279 | F21: =F2*Inputs!F6*F19*Inputs!F7 -> 0.016969099
A22: min_h | B22: human talk minutes per due | C22: =C3*Inputs!C6*(C19*C5+(C20-C19)*Inputs!$C$18)+C21*Inputs!$C$26 -> 0.24298834 | D22: =D3*Inputs!D6*(D19*D5+(D20-D19)*Inputs!$C$18)+D21*Inputs!$C$26 -> 0.83487966 | E22: =E3*Inputs!E6*(E19*E5+(E20-E19)*Inputs!$C$18)+E21*Inputs!$C$26 -> 0.47954673 | F22: =F3*Inputs!F6*(F19*F5+(F20-F19)*Inputs!$C$18)+F21*Inputs!$C$26 -> 0.61998917
A23: human_cost_T | B23: desk cost per due, talk-minute method | C23: =C22*Inputs!$C$25 -> 1.8224125 | D23: =D22*Inputs!$C$25 -> 6.2615975 | E23: =E22*Inputs!$C$25 -> 3.5966005 | F23: =F22*Inputs!$C$25 -> 4.6499187
A24: human_cost_S | B24: desk cost per due, seat method | C24: =Inputs!C6*Inputs!$C$27/Inputs!$C$28 -> 5.6 | D24: =Inputs!D6*Inputs!$C$27/Inputs!$C$28 -> 14.933333 | E24: =Inputs!E6*Inputs!$C$27/Inputs!$C$28 -> 14.933333 | F24: =Inputs!F6*Inputs!$C$27/Inputs!$C$28 -> 14.933333
A25: v | B25: commission per save, this year = c*P | C25: =Inputs!C3*Inputs!C2 -> 225 | D25: =Inputs!D3*Inputs!D2 -> 1980 | E25: =Inputs!E3*Inputs!E2 -> 2550 | F25: =Inputs!F3*Inputs!F2 -> 1500
A26: v_ltv | B26: 3-year commission value | C26: =C25*(1+Inputs!C9/(1+Inputs!$C$36)+(Inputs!C9/(1+Inputs!$C$36))^2) -> 389.75008 | D26: =D25*(1+Inputs!D9/(1+Inputs!$C$36)+(Inputs!D9/(1+Inputs!$C$36))^2) -> 3795.9997 | E26: =E25*(1+Inputs!E9/(1+Inputs!$C$36)+(Inputs!E9/(1+Inputs!$C$36))^2) -> 6069.4635 | F26: =F25*(1+Inputs!F9/(1+Inputs!$C$36)+(Inputs!F9/(1+Inputs!$C$36))^2) -> 3673.9477
A27: vp_cost_launch | B27: VP cost per worked due at launch COGS | C27: =C16*(Inputs!$C$32+Inputs!$C$29)+C3*C14*Inputs!$C$21+Inputs!$C$20*Inputs!$C$34+C3*C9*Inputs!$C$22*Inputs!$C$23*Inputs!$C$24 -> 8.1460032 | D27: =D16*(Inputs!$C$32+Inputs!$C$29)+D3*D14*Inputs!$C$21+Inputs!$C$20*Inputs!$C$34+D3*D9*Inputs!$C$22*Inputs!$C$23*Inputs!$C$24 -> 10.053547 | E27: =E16*(Inputs!$C$32+Inputs!$C$29)+E3*E14*Inputs!$C$21+Inputs!$C$20*Inputs!$C$34+E3*E9*Inputs!$C$22*Inputs!$C$23*Inputs!$C$24 -> 6.3812894 | F27: =F16*(Inputs!$C$32+Inputs!$C$29)+F3*F14*Inputs!$C$21+Inputs!$C$20*Inputs!$C$34+F3*F9*Inputs!$C$22*Inputs!$C$23*Inputs!$C$24 -> 7.787418
A28: vp_cost_scale | B28: VP cost per worked due at scale COGS | C28: =C16*(Inputs!$C$33+Inputs!$C$29)+C3*C14*Inputs!$C$21+Inputs!$C$20*Inputs!$C$34+C3*C9*Inputs!$C$22*Inputs!$C$23*Inputs!$C$24 -> 5.2168441 | D28: =D16*(Inputs!$C$33+Inputs!$C$29)+D3*D14*Inputs!$C$21+Inputs!$C$20*Inputs!$C$34+D3*D9*Inputs!$C$22*Inputs!$C$23*Inputs!$C$24 -> 6.2180509 | E28: =E16*(Inputs!$C$33+Inputs!$C$29)+E3*E14*Inputs!$C$21+Inputs!$C$20*Inputs!$C$34+E3*E9*Inputs!$C$22*Inputs!$C$23*Inputs!$C$24 -> 4.1579751 | F28: =F16*(Inputs!$C$33+Inputs!$C$29)+F3*F14*Inputs!$C$21+Inputs!$C$20*Inputs!$C$34+F3*F9*Inputs!$C$22*Inputs!$C$23*Inputs!$C$24 -> 4.9118813
A29: renewals_ai | B29: renewal rate on AI-worked list | C29: =Inputs!C4+C15 -> 0.52759934 | D29: =Inputs!D4+D15 -> 0.65643589 | E29: =Inputs!E4+E15 -> 0.85805948 | F29: =Inputs!F4+F15 -> 0.82257435
A30: fc_max_nocall | B30: buyer's max fee per renewal vs no calling | C30: =C15*C25/C29 -> 33.093014 | D30: =D15*D25/D29 -> 170.22692 | E30: =E15*E25/E29 -> 53.66957 | F30: =F15*F25/F29 -> 41.165315
A31: fc_max_vs_desk_T | B31: buyer's max fee per renewal vs own desk (talk method) | C31: =((C15-C21)*C25+C23)/C29 -> 27.218691 | D31: =((D15-D21)*D25+D23)/D29 -> 51.806453 | E31: =((E15-E21)*E25+E23)/E29 -> 17.51781 | F31: =((F15-F21)*F25+F23)/F29 -> 15.874313
A32: fc_max_vs_desk_S | B32: buyer's max fee per renewal vs own desk (seat method) | C32: =((C15-C21)*C25+C24)/C29 -> 34.378646 | D32: =((D15-D21)*D25+D24)/D29 -> 65.016784 | E32: =((E15-E21)*E25+E24)/E29 -> 30.729869 | F32: =((F15-F21)*F25+F24)/F29 -> 28.375815
A33: fc_floor_launch | B33: VP min fee per renewal for gm_target at launch | C33: =C27/((1-Inputs!$C$37)*C29) -> 25.732921 | D33: =D27/((1-Inputs!$C$37)*D29) -> 25.525587 | E33: =E27/((1-Inputs!$C$37)*E29) -> 12.394808 | F33: =F27/((1-Inputs!$C$37)*F29) -> 15.778549
A34: fs_floor_launch | B34: VP min fee per incremental save for gm_target at launch | C34: =C27/((1-Inputs!$C$37)*C15) -> 174.95859 | D34: =D27/((1-Inputs!$C$37)*D15) -> 296.9017 | E34: =E27/((1-Inputs!$C$37)*E15) -> 588.91397 | F34: =F27/((1-Inputs!$C$37)*F15) -> 574.94577
A35: revenue_per_due | B35: VP revenue per worked due at the fee | C35: =Inputs!C40*C29 -> 10.551987 | D35: =Inputs!D40*D29 -> 32.821794 | E35: =Inputs!E40*E29 -> 12.870892 | F35: =Inputs!F40*F29 -> 12.338615
A36: gm_launch | B36: VP gross margin at the fee, launch COGS | C36: =(C35-C27)/C35 -> 0.22801238 | D36: =(D35-D27)/D35 -> 0.69369296 | E36: =(E35-E27)/E35 -> 0.50420769 | F36: =(F35-F27)/F35 -> 0.36885803
A37: gm_scale | B37: VP gross margin at the fee, 1M min/month COGS | C37: =(C35-C28)/C35 -> 0.50560552 | D37: =(D35-D28)/D35 -> 0.81055116 | E37: =(E35-E28)/E35 -> 0.67694741 | F37: =(F35-F28)/F35 -> 0.60190985
A38: yield_per_min | B38: effective INR per AI-connected minute at the fee | C38: =C35/C16 -> 10.158753 | D38: =D35/D16 -> 24.131811 | E38: =E35/E16 -> 16.325139 | F38: =F35/F16 -> 12.100313
A39: buyer_net_nocall_per_1000 | B39: buyer net gain per 1,000 worked due vs no calling, INR | C39: =1000*(C15*C25-C35) -> 6907.8657 | D39: =1000*(D15*D25-D35) -> 78921.262 | E39: =1000*(E15*E25-E35) -> 33180.792 | F39: =1000*(F15*F25-F35) -> 21522.917
A40: kc1_due_per_month_3_seats_T | B40: due/month a 3-seat desk works (talk method) | C40: =3*Inputs!$C$38/C22 -> 59262.104 | D40: =3*Inputs!$C$38/D22 -> 17247.995 | E40: =3*Inputs!$C$38/E22 -> 30028.356 | F40: =3*Inputs!$C$38/F22 -> 23226.212
...

Sheet MC_results
A1: VALUES from renewal_model.py (seed 20261017, n=20,000). Per 1,000 due where labelled.
A2: line | B2: metric | C2: p10 | D2: p50 | E2: p90 | F2: mean
A3: 2W_motor | B3: value_per_save_inr | C3: 161.8302 | D3: 265.1795 | E3: 413.2644 | F3: 278.2573
A4: 2W_motor | B4: value_per_save_3yr_ltv_inr | C4: 278.2315 | D4: 457.9616 | E4: 721.1534 | F4: 482.8793
A5: 2W_motor | B5: baseline_renewal_rate | C5: 0.3668 | D5: 0.4494 | E5: 0.5334 | F5: 0.4499
A6: 2W_motor | B6: incremental_renewals_ai_per_1000_due | C6: 43.8789 | D6: 71.0018 | E6: 106.7536 | F6: 73.6386
A7: 2W_motor | B7: incremental_renewals_human_per_1000_due | C7: 9.5092 | D7: 19.7603 | E7: 37.2388 | F7: 21.813
A8: 2W_motor | B8: ai_reach_rpc | C8: 0.5681 | D8: 0.6892 | E8: 0.7912 | F8: 0.6839
A9: 2W_motor | B9: ai_attempts_per_1000_due | C9: 1999.9369 | D9: 2439.3066 | E9: 2930.5164 | F9: 2454.2732
A10: 2W_motor | B10: ai_connected_minutes_per_1000_due | C10: 802.7539 | D10: 1077.2105 | E10: 1402.9298 | F10: 1092.6709
A11: 2W_motor | B11: human_minutes_per_1000_due | C11: 125.6644 | D11: 244.7563 | E11: 432.2795 | F11: 264.8845
A12: 2W_motor | B12: human_cost_inr_per_1000_due | C12: 996.1019 | D12: 1986.5315 | E12: 3588.4419 | F12: 2166.4424
A13: 2W_motor | B13: human_cost_inr_per_renewal_collected | C13: 2.1057 | D13: 4.2365 | E13: 7.7782 | F13: 4.6591
A14: 2W_motor | B14: human_cost_inr_per_1000_due_seat_method | C14: 2992.1386 | D14: 5432.1349 | E14: 9485.876 | F14: 5917.7966
... A31: 2W_motor | B31: holdout_cost_inr_per_1000_due | C31: 952.6882 | D31: 1842.7228 | E31: 3420.3176 | F31: 2049.469
A32: 2W_motor | B32: P(value_per_save >= 150) | F32: 0.9302
A33: 2W_motor | B33: P(window per-renewal fee exists vs no-call, launch GM40) | F33: 0.6557
A34: 2W_motor | B34: P(window per-renewal fee exists vs no-call, scale GM50) | F34: 0.8014
A35: 2W_motor | B35: P(window per-renewal fee exists vs human desk, launch GM40) | F35: 0.4846
A36: 2W_motor | B36: P(window per-renewal fee exists vs human desk, scale GM50) | F36: 0.6771
A37: 2W_motor | B37: P(AI incremental > human incremental) | F37: 0.9999
A38: 2W_motor | B38: P(VP cost per worked due < human cost per due) | F38: 0
A39: 2W_motor | B39: P(VP cost per worked due < human cost per due), scale | F39: 0.0032
A40: 2W_motor | B40: P(VP cost per worked due < human cost per due, seat method), launch | F40: 0.1495
A41: 4W_motor | B41: value_per_save_inr | C41: 1439.907 | D41: 2414.5269 | E41: 3880.9465 | F41: 2552.5168
A42: 4W_motor | B42: value_per_save_3yr_ltv_inr | C42: 2746.5003 | D42: 4623.3073 | E42: 7461.0776 | F42: 4900.3818
A43: 4W_motor | B43: baseline_renewal_rate | C43: 0.5179 | D43: 0.6011 | E43: 0.6843 | F43: 0.6009
A44: 4W_motor | B44: incremental_renewals_ai_per_1000_due | C44: 31.2484 | D44: 51.0497 | E44: 78.7743 | F44: 53.4096
A45: 4W_motor | B45: incremental_renewals_human_per_1000_due | C45: 18.2495 | D45: 34.1269 | E45: 57.8551 | F45: 36.4607
A46: 4W_motor | B46: ai_reach_rpc | C46: 0.5681 | D46: 0.6892 | E46: 0.7912 | F46: 0.6839
A47: 4W_motor | B47: ai_attempts_per_1000_due | C47: 1959.6495 | D47: 2387.3938 | E47: 2879.8719 | F47: 2405.459
A48: 4W_motor | B48: ai_connected_minutes_per_1000_due | C48: 1009.3955 | D48: 1391.1532 | E48: 1852.6857 | F48: 1414.2178
A49: 4W_motor | B49: human_minutes_per_1000_due | C49: 433.0572 | D49: 742.3214 | E49: 1157.9245 | F49: 774.5436
A50: 4W_motor | B50: human_cost_inr_per_1000_due | C50: 3407.6766 | D50: 6017.2791 | E50: 9675.5483 | F50: 6336.0516
A51: 4W_motor | B51: human_cost_inr_per_renewal_collected | C51: 5.3454 | D51: 9.4548 | E51: 15.4855 | F51: 10.0222
A52: 4W_motor | B52: human_cost_inr_per_1000_due_seat_method | C52: 8409.9122 | D52: 12812.649 | E52: 19941.95 | F52: 13617.959
... A69: 4W_motor | B69: holdout_cost_inr_per_1000_due | C69: 5978.9111 | D69: 12132.946 | E69: 23152.886 | F69: 13635.284
A70: 4W_motor | B70: P(value_per_save >= 150) | F70: 1
A71: 4W_motor | B71: P(window per-renewal fee exists vs no-call, launch GM40) | F71: 0.9997
A72: 4W_motor | B72: P(window per-renewal fee exists vs no-call, scale GM50) | F72: 1
...

Sheet Pricing_grid
A1: VALUES from renewal_model.py: VP revenue, buyer gain and VP GM by fee and scheme.
A2: line | B2: scheme | C2: fee_inr | D2: vp_revenue_per_1000_due_p50 | E2: buyer_net_vs_nocall_per_1000_due_p50 | F2: p_buyer_gains_vs_nocall | G2: p_buyer_gains_vs_human_desk | H2: p_buyer_gains_vs_human_desk_seat_method | I2: fee_as_share_of_commission_gain_p50 | J2: yield_inr_per_ai_minute_p50 | K2: vp_gm_p50_launch_100k | L2: p_gm_ge_40_launch_100k | M2: vp_gm_p50_scale_1M | N2: p_gm_ge_40_scale_1M
A3: 2W_motor | B3: per_renewal_collected | C3: 5 | D3: 2361 | E3: 14251 | F3: 1 | G3: 1 | H3: 1 | I3: 0.141 | J3: 2.42 | K3: -2.492 | L3: 0 | M3: -1.304 | N3: 0
A4: 2W_motor | B4: per_renewal_collected | C4: 10 | D4: 4722 | E4: 11933 | F4: 0.991 | G4: 0.988 | H4: 1 | I4: 0.282 | J4: 4.84 | K4: -0.746 | L4: 0 | M4: -0.152 | N4: 0.006
A5: 2W_motor | B5: per_renewal_collected | C5: 15 | D5: 7083 | E5: 9572 | F5: 0.948 | G5: 0.911 | H5: 0.99 | I5: 0.422 | J5: 7.26 | K5: -0.164 | L5: 0.005 | M5: 0.232 | N5: 0.168
A6: 2W_motor | B6: per_renewal_collected | C6: 20 | D6: 9444 | E6: 7234 | F6: 0.861 | G6: 0.77 | H6: 0.936 | I6: 0.563 | J6: 9.68 | K6: 0.127 | L6: 0.074 | M6: 0.424 | N6: 0.564
A7: 2W_motor | B7: per_renewal_collected | C7: 25 | D7: 11805 | E7: 4894 | F7: 0.748 | G7: 0.609 | H7: 0.828 | I7: 0.704 | J7: 12.1 | K7: 0.302 | L7: 0.278 | M7: 0.539 | N7: 0.849
A8: 2W_motor | B8: per_renewal_collected | C8: 30 | D8: 14167 | E8: 2560 | F8: 0.625 | G8: 0.461 | H8: 0.68 | I8: 0.845 | J8: 14.52 | K8: 0.418 | L8: 0.548 | M8: 0.616 | N8: 0.963
A9: 2W_motor | B9: per_renewal_collected | C9: 40 | D9: 18889 | E9: -2084 | F9: 0.409 | G9: 0.245 | H9: 0.4 | I9: 1.126 | J9: 19.36 | K9: 0.563 | L9: 0.898 | M9: 0.712 | N9: 0.999
A10: 2W_motor | B10: per_renewal_collected | C10: 50 | D10: 23611 | E10: -6756 | F10: 0.247 | G10: 0.123 | H10: 0.21 | I10: 1.408 | J10: 24.2 | K10: 0.651 | L10: 0.988 | M10: 0.77 | N10: 1
A11: 2W_motor | B11: per_renewal_collected | C11: 60 | D11: 28333 | E11: -11328 | F11: 0.144 | G11: 0.06 | H11: 0.105 | I11: 1.689 | J11: 29.04 | K11: 0.709 | L11: 0.999 | M11: 0.808 | N11: 1
A12: 2W_motor | B12: per_renewal_collected | C12: 75 | D12: 35416 | E12: -18274 | F12: 0.06 | G12: 0.019 | H12: 0.034 | I12: 2.112 | J12: 36.3 | K12: 0.767 | L12: 1 | M12: 0.846 | N12: 1
A13: 2W_motor | B13: per_renewal_collected | C13: 100 | D13: 47222 | E13: -29899 | F13: 0.014 | G13: 0.002 | H13: 0.005 | I13: 2.816 | J13: 48.41 | K13: 0.825 | L13: 1 | M13: 0.885 | N13: 1
A14: 2W_motor | B14: per_renewal_collected | C14: 150 | D14: 70833 | E14: -53142 | F14: 0 | G14: 0 | H14: 0 | I14: 4.223 | J14: 72.61 | K14: 0.884 | L14: 1 | M14: 0.923 | N14: 1
... A102: life_yr2plus | B102: per_ai_minute_yield | C102: 8 | D102: 7161 | E102: 29291 | F102: 0.998 | G102: 0.815 | H102: 0.959 | I102: 0.195 | J102: 8 | K102: -0.041 | L102: 0 | M102: 0.322 | N102: 0.219

Sheet Buyers
A1: VALUES: buyer archetypes at the concept-test fees (archetype sizes are assumptions).
A2: buyer | B2: due_per_month | C2: mix | D2: vp_revenue_month_p50 | E2: vp_revenue_trough_month_p50 | F2: buyer_commission_gain_month_p50 | G2: buyer_commission_gain_month_p10 | H2: vp_gm_launch_p50 | I2: vp_gm_scale_p50 | J2: human_desk_seats_equivalent_p50 | K2: human_desk_seats_seat_method_p50 | L2: supports_min_25k_in_trough | M2: max_min_fee_at_50pct_of_gain_p50
A3: small_IMF_or_agency | B3: 150 | C3: {"2W_motor": 0.5, "4W_motor": 0.2, "health": 0.2, "life_yr2plus": 0.1} | D3: 2103 | E3: 1704 | F3: 6714 | G3: 4277 | H3: 0.42 | I3: 0.621 | J3: 0.01 | K3: 0.05 | L3: False | M3: 3357
A4: mid_retail_broker_or_CA | B4: 1500 | C4: {"2W_motor": 0.4, "4W_motor": 0.3, "health": 0.25, "life_yr2plus": 0.05} | D4: 24068 | E4: 19653 | F4: 81195 | G4: 49753 | H4: 0.486 | I4: 0.665 | J4: 0.15 | K4: 0.51 | L4: False | M4: 40597
A5: large_PoSP_platform | B5: 25000 | C5: {"2W_motor": 0.5, "4W_motor": 0.3, "health": 0.15, "life_yr2plus": 0.05} | D5: 395869 | E5: 319839 | F5: 1283549 | G5: 778550 | H5: 0.468 | I5: 0.653 | J5: 2.36 | K5: 7.92 | L5: True | M5: 641775

Sheet MDE
A1: VALUES: minimum detectable lift (pp) for a holdout, 80% power, alpha 0.05 two-sided.
A2: line | B2: due_per_month | C2: holdout | D2: baseline | E2: mde_pp_one_month | F2: median_modelled_lift_pp | G2: months_to_detect_median_lift
A3: 2W_motor | B3: 150 | C3: 0.1 | D3: 0.45 | E3: 37.93 | F3: 7.1 | G3: 28.5
A4: 2W_motor | B4: 150 | C4: 0.2 | D4: 0.45 | E4: 28.45 | F4: 7.1 | G4: 16.1
A5: 2W_motor | B5: 500 | C5: 0.1 | D5: 0.45 | E5: 20.78 | F5: 7.1 | G5: 8.6
A6: 2W_motor | B6: 500 | C6: 0.2 | D6: 0.45 | E6: 15.58 | F6: 7.1 | G6: 4.8
A7: 2W_motor | B7: 1500 | C7: 0.1 | D7: 0.45 | E7: 12 | F7: 7.1 | G7: 2.9
A8: 2W_motor | B8: 1500 | C8: 0.2 | D8: 0.45 | E8: 9 | F8: 7.1 | G8: 1.6
A9: 2W_motor | B9: 5000 | C9: 0.1 | D9: 0.45 | E9: 6.57 | F9: 7.1 | G9: 0.9
A10: 2W_motor | B10: 5000 | C10: 0.2 | D10: 0.45 | E10: 4.93 | F10: 7.1 | G10: 0.5
A11: 2W_motor | B11: 25000 | C11: 0.1 | D11: 0.45 | E11: 2.94 | F11: 7.1 | G11: 0.2
A12: 2W_motor | B12: 25000 | C12: 0.2 | D12: 0.45 | E12: 2.2 | F12: 7.1 | G12: 0.1
A13: 4W_motor | B13: 150 | C13: 0.1 | D13: 0.6 | E13: 37.35 | F13: 5.1 | G13: 53.5
A14: 4W_motor | B14: 150 | C14: 0.2 | D14: 0.6 | E14: 28.02 | F14: 5.1 | G14: 30.1
... A42: life_yr2plus | B42: 25000 | C42: 0.2 | D42: 0.8 | E42: 1.77 | F42: 2.12 | G42: 0.7

Sheet Sensitivity
A1: VALUES: Spearman rank correlation of each input with outputs at the concept-test fee.
A2: line | B2: input | C2: rho_buyer_net_vs_desk | D2: rho_buyer_net_vs_nocall | E2: rho_vp_gm_launch
A3: 2W_motor | B3: P | C3: 0.493 | D3: 0.552 | E3: -0.005
A4: 2W_motor | B4: c | C4: 0.381 | D4: 0.432 | E4: 0.004
A5: 2W_motor | B5: b0 | C5: -0.379 | D5: -0.347 | E5: 0.567
A6: 2W_motor | B6: s_pre | C6: 0.009 | D6: 0.014 | E6: 0.081
A7: 2W_motor | B7: covH | C7: -0.153 | D7: -0.005 | E7: 0.011
A8: 2W_motor | B8: persH | C8: 0.412 | D8: 0.46 | E8: 0.019
A9: 2W_motor | B9: m_rpc | C9: 0.041 | D9: -0.004 | E9: -0.407
A10: 2W_motor | B10: r_future | C10: 0.006 | D10: 0.009 | E10: 0.001
A11: 2W_motor | B11: p_ans | C11: 0.083 | D11: 0.095 | E11: -0.186
A12: 2W_motor | B12: q_rpc | C12: 0.036 | D12: 0.047 | E12: -0.027
A13: 2W_motor | B13: r_max | C13: 0.097 | D13: 0.096 | E13: -0.151
A14: 2W_motor | B14: f1600 | C14: 0.093 | D14: 0.073 | E14: -0.121
... A114: life_yr2plus | B114: K_H | C114: -0.435 | D114: 0.003 | E114: -0.01

Sheet Expansion
A1: VALUES from expansion_sizing.py (seed 20261018): serviceable market by stage, INR crore/yr, as of 2026-10.
A2: stage | B2: as_of | C2: unit | D2: p10 | E2: p50 | F2: p90
A3: S0 beachhead: intermediaries' renewal books (per renewal) | B3: 2026-10 | C3: INR crore / yr | D3: 89 | E3: 107 | F3: 127
A4: S0 excluding the largest broker/PoSP platforms (in-house renewal ops) | B4: 2026-10 | C4: INR crore / yr | D4: 46 | E4: 58 | F4: 73
A5: S1 insurers' renewal desks ex-LIC (per renewal, insurer fees) | B5: 2026-10 | C5: INR crore / yr | D5: 36 | E5: 51 | F5: 72
A6: S2 other BFSI 1600 service calls, mid-market (per minute) | B6: 2026-10 | C6: INR crore / yr | D6: 94 | E6: 166 | F6: 283
A7: S3 rest of post-sales outside BFSI (l3, haircut) | B7: 2026-10 | C7: INR crore / yr | D7: 751 | E7: 1980 | F7: 6163
A8: S0+S1 at per-minute list prices (cross-check) | B8: 2026-10 | C8: INR crore / yr | D8: 72 | E8: 99 | F8: 136
A9: LIC renewal book at per-minute prices (not serviceable; context) | B9: 2026-10 | C9: INR crore / yr | D9: 80 | E9: 111 | F9: 153
A10: All insurance renewal calling incl. LIC, per minute (ceiling) | B10: 2026-10 | C10: INR crore / yr | D10: 154 | E10: 211 | F10: 288
A11: Cumulative S0..S3 after the beachhead | B11: 2026-10 | C11: INR crore / yr | D11: 1089 | E11: 2316 | F11: 6484
A12: l3 total SAM, all 19 segments (round 1, unhaircut) | B12: 2026-10 | C12: INR crore / yr | D12: 5127 | E12: 9618 | F12: 20524

Sheet TRAI_check
A1: VALUES: corrected direction of the TRAI 1600/140 comparison (l3v section 7).
A2: comparison | B2: ratio_p10 | C2: ratio_p50 | D2: ratio_p90 | E2: p_ratio_gt_1 | F2: reading
A3: l3 as published: bottom-up BFSI post-sales minutes / ALL national 1600 minutes | B3: 0.39 | C3: 1.36 | D3: 5.16 | E3: 0.622 | F3: subset over total; must be < 1 if in-reach calls run on 1600
A4: corrected: bottom-up BFSI post-sales minutes / (1600 minutes x in-reach share) | B4: 1.52 | C4: 5.59 | D4: 22.49 | E4: 0.956 | F4: > 1 means the bottom-up seat model is high OR in-reach calling runs off-series (10-digit)
A5: corrected: bottom-up insurance-renewal minutes / (1600 minutes x insurance share x in-reach share) | B5: 0.61 | C5: 4.37 | D5: 30.88 | E5: 0.83 | F5: IRDAI entities had to be on 1600 from 2026-02-15; Q1 FY27 is after the deadline
A6: l3 as published: bottom-up pre-sales minutes / ALL 140 minutes (originated) | B6: 0.56 | C6: 1.39 | D6: 3.86 | E6: 0.674 | F6: subset over total
A7: corrected: bottom-up pre-sales minutes / (delivered 140 minutes x in-reach share) | B7: 1.96 | C7: 5.12 | D7: 14.81 | E7: 0.989 | F7: uses 11.68 bn delivered calls/qtr, not 13.16 bn originated
A8: context: AI-flagged suspected-spam calls per quarter (10-digit series) | F8: 22.99 bn/qtr vs 1.15 bn 1600 and 13.16 bn 140 [prim PR 111/2026]

Sheet Incumbents
A1: VALUES: incumbent revenue (MCA via press = read-secondary) x assumed voice-agent share.
A2: company | B2: fy | C2: revenue_cr_low | D2: revenue_cr_high | E2: voice_agent_share_low | F2: voice_agent_share_mode | G2: voice_agent_share_high | H2: implied_voice_agent_rev_cr_p50 | I2: source | J2: method | K2: note
A3: Exotel | B3: FY25 | C3: 490.5 | D3: 490.5 | E3: 0.02 | F3: 0.05 | G3: 0.1 | H3: 27.1 | I3: Entrackr/MediaNama RoC 2026-01 (l4a, l4c) | J3: read-secondary (MCA via press) x assumption share | K3: CPaaS; telephony cost 212 Cr = 44% of costs; voicebot/AgentStream share unknown
A4: Gnani.ai | B4: FY25 | C4: 53.9 | D4: 57 | E4: 0.5 | F4: 0.7 | G4: 0.9 | H4: 38.8 | I4: Inc42 / Entrepreneur (l4a) | J4: read-secondary (MCA via press) x assumption share | K4: voice AI + speech analytics; some non-India revenue
A5: Sarvam AI | B5: FY25 | C5: 29.1 | D5: 29.1 | E5: 0.1 | F5: 0.3 | G5: 0.6 | H5: 9.5 | I5: Inc42 from MCA (l4a) | J5: read-secondary (MCA via press) x assumption share | K5: models/APIs/enterprise/government; voice agents a part
A6: SquadStack | B6: FY24 | C6: 26.5 | D6: 26.5 | E6: 0.1 | F6: 0.3 | G6: 0.5 | H6: 7.9 | I6: Inc42 (l4a) | J6: read-secondary (MCA via press) x assumption share | K6: human + AI telecalling; AI share unknown; FY24 down 50%
A7: Yellow.ai | B7: FY25 | C7: 233.6 | D7: 235.9 | E7: 0.03 | F7: 0.08 | G7: 0.15 | H7: 20.1 | I7: Inc42 (l4a) | J7: read-secondary (MCA via press) x assumption share | K7: global CX automation; voice x India-domestic share
A8: Haptik | B8: FY25 | C8: 156.6 | D8: 231.1 | E8: 0.02 | F8: 0.05 | G8: 0.1 | H8: 10.6 | I8: lapaasvoice (unverified) / Inc42 FY24 (l4a) | J8: read-secondary (MCA via press) x assumption share | K8: Jio-group heavy; chat-first
A9: Ozonetel | B9: FY24 | C9: 110.3 | D9: 110.3 | E9: 0.02 | F9: 0.05 | G9: 0.1 | H9: 6.1 | I9: Inc42 (l4a) | J9: read-secondary (MCA via press) x assumption share | K9: cloud contact centre; AI bot share unknown
A10: Knowlarity (Gupshup) | B10: FY25 | C10: 87.8 | D10: 87.8 | E10: 0.01 | F10: 0.03 | G10: 0.08 | H10: 3.4 | I10: Inc42 (l4c) | J10: read-secondary (MCA via press) x assumption share | K10: cloud telephony
A11: Uniphore (India entity) | B11: FY24 | C11: 194.2 | D11: 194.2 | E11: 0.02 | F11: 0.06 | G11: 0.12 | H11: 12.7 | I11: Inc42 (l4a) | J11: read-secondary (MCA via press) x assumption share | K11: global; India entity largely serves global work
A12: LeadSquared | B12: FY25 | C12: 326.2 | D12: 326.2 | E12: 0 | F12: 0.005 | G12: 0.02 | H12: 2.5 | I12: Entrackr RoC 2025-10 (l4c) | J12: read-secondary (MCA via press) x assumption share | K12: CRM; Invorto voice AI new
A13: Bolna | B13: run-rate Jan 2026 | C13: 6 | D13: 6 | E13: 0.8 | F13: 0.9 | G13: 1 | H13: 5.4 | I13: Inc42 Jan 2026 (l4a) | J13: read-secondary (MCA via press) x assumption share | K13: ~0.5 Cr/month run-rate
A14: Ringg AI | B14: FY25 | C14: 0.905 | D14: 0.905 | E14: 0.9 | F14: 1 | G14: 1 | H14: 0.9 | I14: Inc42 (l4a) | J14: read-secondary (MCA via press) x assumption share
A15: smallest.ai (India entity) | B15: FY25 | C15: 0.932 | D15: 0.932 | E15: 0.5 | F15: 0.8 | G15: 1 | H15: 0.7 | I15: Inc42 (l4a) | J15: read-secondary (MCA via press) x assumption share | K15: parent books US revenue
A16: Convin | B16: FY24 | C16: 9.1 | D16: 9.1 | E16: 0 | F16: 0.05 | G16: 0.2 | H16: 0.7 | I16: Inc42 (l4a) | J16: read-secondary (MCA via press) x assumption share | K16: QA/analytics, not agents
A17: TOTAL implied Indian voice-agent revenue (FY24-26 mix) | B17: mixed | H17: 148.4 | I17: sum of rows | J17: computed | K17: p10 132 / p90 165 Cr
A18: Implied AI penetration of l3 total SAM (revenue / SAM) | H18: 1.54 | J18: computed (percent) | K18: p10 0.71% / p90 2.92%
A19: Gnani+SquadStack voice revenue vs l3 insurance-renewal SAM (ratio) | J19: computed | K19: not computable: neither discloses an insurance-renewal revenue split; both sell mainly to insurers, not intermediaries

Sheet IRDAI_extracts
A1: VALUES: IRDAI Handbook 2024-25 tables T44, T50, T99, T103, T104 (extract_irdai_handbook.py).
A2: table | B2: year | C2: segment | D2: channel | E2: metric | F2: value
A3: T103 | B3: 2024-25 | C3: Motor Own Damage | D3: Individual Agents | E3: gross_direct_premium_inr_cr | F3: 8619.77
A4: T103 | B4: 2024-25 | C4: Motor Own Damage | D4: Corporate Agents - Banks | E4: gross_direct_premium_inr_cr | F4: 784.33
A5: T103 | B5: 2024-25 | C5: Motor Own Damage | D5: Corporate Agents - Others | E5: gross_direct_premium_inr_cr | F5: 2423.96
A6: T103 | B6: 2024-25 | C6: Motor Own Damage | D6: Brokers | E6: gross_direct_premium_inr_cr | F6: 23202.1
A7: T103 | B7: 2024-25 | C7: Motor Own Damage | D7: Referral Arrangements | E7: gross_direct_premium_inr_cr | F7: 0
A8: T103 | B8: 2024-25 | C8: Motor Own Damage | D8: Direct Business | E8: gross_direct_premium_inr_cr | F8: 1194.67
A9: T103 | B9: 2024-25 | C9: Motor Own Damage | D9: Micro Insurance Agents | E9: gross_direct_premium_inr_cr | F9: 1.16
A10: T103 | B10: 2024-25 | C10: Motor Own Damage | D10: Others | E10: gross_direct_premium_inr_cr | F10: 3909.21
A11: T103 | B11: 2024-25 | C11: Motor Own Damage | D11: Total | E11: gross_direct_premium_inr_cr | F11: 40135.21
A12: T103 | B12: 2024-25 | C12: Motor Third Party | D12: Individual Agents | E12: gross_direct_premium_inr_cr | F12: 20185.88
A13: T103 | B13: 2024-25 | C13: Motor Third Party | D13: Corporate Agents - Banks | E13: gross_direct_premium_inr_cr | F13: 820.24
A14: T103 | B14: 2024-25 | C14: Motor Third Party | D14: Corporate Agents - Others | E14: gross_direct_premium_inr_cr | F14: 3455.89
... A153: T44 | B153: 2024-25 | C153: health | D153: Grand Total | E153: incurred_claims_ratio_pct | F153: 85.34
