Workbook

Sheet README
A1: VP voice-stack pricing model, 2026-10-19 (synthesis lane). Source of truth: model/pricing_model.py.
A2: Yellow cells on Params are editable inputs. Budget, Calc and Tiers are LIVE FORMULAS on Params.
A3: Live_g5, MC, Volume, Sensitivity, Latency and Calibration are VALUES pasted from results/*.csv.
A4: Calc covers cascades and tiers. Gemini Live is not a closed-form formula (per-invocation re-billing): use Live_g5.
A5: Deterministic case = g3 reference shape: 5 exchanges/min, agent 24 s/min, caller 24 s/min, FX 95, 2026 prices.
A6: OpenRouter-routed LLM rows include the 5.5% credit fee and a 1.2x ledger factor (g3 verify.md #7).
A7: Telephony per connected minute = rate x (L + 0.25)/L: 30-second pulses add 15 s per call on average.
A8: Prices are ex-GST. Input GST (incl. reverse-charge IGST on imported services) is assumed recoverable as ITC.
A9: Calc column 'diff' = formula AI minus python AI; it must be ~0 after recalculation (python3 build_xlsx.py --check).
A10: Every number on Inputs carries its lane file, date and method. No number here was invented: ranges marked 'assumption' are modelling choices.

Sheet Inputs
A1: key | B1: value | C1: lo | D1: hi | E1: unit | F1: source | G1: date | H1: method | I1: note
A2: fx | B2: 95 | C2: 90 | D2: 100 | E2: INR per USD | F2: task instruction; g2 verify read Pluang mid-market 94.95 on 2026-10-19 | G2: 2026-10-19 | H2: assumption | I2: MC uniform 90-100
A3: exch_per_min | B3: 5 | C3: 3 | D3: 7 | E3: caller-agent exchanges per connected minute | F3: lanes/g3-cascade-measured/results/rederived_usage_per_exchange.csv (battery 3.15-4.96); g5 Live 3.7-7.3 billed turns/min | G3: 2026-10-18 | H3: assumption | I3: MC triangular(3,5,7)
A4: agent_s | B4: 24 | C4: 15 | D4: 40 | E4: seconds of agent speech per connected minute | F4: g3 reference shape; g5/g2 Live calls 20-41 s (lanes/g2.../verify.md #7) | G4: 2026-10-18 | H4: assumption | I4: MC triangular(15,24,40)
A5: caller_s | B5: 24 | C5: 12 | D5: 32 | E5: seconds of caller speech per connected minute | F5: g3 reference shape; g5 Live sessions.csv 13-19 s VAD speech | G5: 2026-10-18 | H5: assumption | I5: MC triangular(12,22,32); agent+caller capped at 56 s
A6: stt_gated_ratio | B6: 1.186 | C6: 1.1 | D6: 1.4 | E6: audio seconds sent per second of caller speech when VAD-gated | F6: lanes/g3-cascade-measured/results/rederived_usage_per_exchange.csv (C1+gated, C6+gated) | G6: 2026-10-18 | H6: measured | I6: n=30 exchanges per gated run; MC uniform
A7: az_stt_usd_h | B7: 1 | E7: USD per audio hour (S1 real-time STT, centralindia) | F7: lanes/g3-cascade-measured/results/cost_inputs.csv; re-read 2026-10-19 (g3 verify.md) | G7: 2026-10-19 | H7: read-primary
A8: az_tts_neural_usd_1m | B8: 15 | E8: USD per 1M chars (S1 Neural TTS) | F8: lanes/g3-cascade-measured/results/cost_inputs.csv | G8: 2026-10-19 | H8: read-primary
A9: az_tts_hd_usd_1m | B9: 22 | E9: USD per 1M chars (Neural HD / DragonHD) | F9: lanes/g3-cascade-measured/results/cost_inputs.csv | G9: 2026-10-19 | H9: read-primary
A10: az_cnv_usd_1m | B10: 24 | E10: USD per 1M chars (S1 Custom Neural Realtime Characters) | F10: model/inputs/azure_custom_voice_centralindia_2026-10-19.json | G10: 2026-10-19 | H10: read-primary
A11: az_cnv_host_usd_h | B11: 4.032 | E11: USD per hour per hosted custom neural voice model | F11: model/inputs/azure_custom_voice_centralindia_2026-10-19.json | G11: 2026-10-19 | H11: read-primary | I11: =usd 2,943/month = inr 2.8 lakh/month per voice at FX 95 -> #VALUE!
A12: cps_az_neural | B12: 10.03 | C12: 9.3 | D12: 10.3 | E12: billed chars per agent-second, hi-IN-SwaraNeural (incl. cancelled requests) | F12: lanes/g3-cascade-measured/results/rederived_usage_per_exchange.csv C1 | G12: 2026-10-18 | H12: measured
A13: cps_az_hd | B13: 17.18 | C13: 15.3 | D13: 17.5 | E13: billed chars per agent-second, en-IN-Aarti DragonHD | F13: lanes/g3-cascade-measured/results/rederived_usage_per_exchange.csv C2 (C3 17.51) | G13: 2026-10-18 | H13: measured
A14: cps_vendor | B14: 14.67 | C14: 11 | D14: 17.5 | E14: billed chars per agent-second, unmeasured vendor voices | F14: lanes/g4-market-selfhost/prices.csv (800 chars/agent-min x 1.10 waste) | G14: 2026-10-18 | H14: assumption
A15: gtl_audio_usd_1m | B15: 3.5 | E15: USD per 1M audio tokens in, gemini-3.5-transcribe-live (25 tok/s) | F15: lanes/g1-gemini-desk/prices.json | G15: 2026-10-18 | H15: read-primary
A16: gtl_text_usd_1m | B16: 21 | E16: USD per 1M text tokens out, gemini-3.5-transcribe-live | F16: lanes/g1-gemini-desk/prices.json | G16: 2026-10-18 | H16: read-primary
A17: gtl_text_tok_per_utt | B17: 14.6 | E17: transcript text tokens per caller utterance | F17: lanes/g3.../results/cost_inputs.csv note (countTokens, not metered) | G17: 2026-10-18 | H17: measured | I17: MC: per-minute text tokens uniform(14.6 x exch, 175 = Google's published estimate)
A18: gem_lite_tts_out_usd_1m_2026 | B18: 6 | E18: USD per 1M audio tokens out, gemini-3.8-flash-lite-tts to 2026-12-31 | F18: lanes/g1-gemini-desk/prices.json | G18: 2026-10-18 | H18: read-primary
A19: gem_lite_tts_out_usd_1m_2027 | B19: 12 | E19: same, from 2027-01-01 (announced) | F19: lanes/g1-gemini-desk/prices.json | G19: 2026-10-18 | H19: read-primary
A20: gem_flash_tts_out_usd_1m_2026 | B20: 9 | E20: USD per 1M audio tokens out, gemini-3.8-flash-tts to 2026-12-31 | F20: lanes/g1-gemini-desk/prices.json | G20: 2026-10-18 | H20: read-primary
A21: gem_flash_tts_out_usd_1m_2027 | B21: 18 | E21: same, from 2027-01-01 (announced) | F21: lanes/g1-gemini-desk/prices.json | G21: 2026-10-18 | H21: read-primary
A22: gem_tts_text_in_usd_1m_2026 | B22: 0.5 | E22: USD per 1M text tokens in, 3.8 TTS models (1.00 from 2027-01-01) | F22: lanes/g1-gemini-desk/prices.json | G22: 2026-10-18 | H22: read-primary
A23: gem_tts_lead_s | B23: 0.25 | E23: leading silence billed per TTS request (s) | F23: lanes/g5-gemini-paid/results/tts_summary.csv (0.14-0.36 s) | G23: 2026-10-18 | H23: measured
A24: flashlite_usd_1m | B24: 0.3 | E24: USD per 1M input tokens, gemini-3.5-flash-lite (cached 0.03, output 2.50); not in the 2027 doubling | F24: lanes/g1-gemini-desk/prices.json | G24: 2026-10-18 | H24: read-primary
A25: live_text_in_usd_1m | B25: 0.75 | E25: USD per 1M, gemini-3.8-live / 3.1-flash-live text in | F25: lanes/g1-gemini-desk/prices.json; g2/g5 verify re-read | G25: 2026-10-19 | H25: read-primary
A26: live_audio_in_usd_1m | B26: 3 | E26: USD per 1M audio tokens in (re-billed every invocation) | F26: lanes/g1-gemini-desk/prices.json | G26: 2026-10-19 | H26: read-primary
A27: live_text_out_usd_1m | B27: 4.5 | E27: USD per 1M text out (thinking, transcripts) | F27: lanes/g1-gemini-desk/prices.json | G27: 2026-10-19 | H27: read-primary
A28: live_audio_out_usd_1m | B28: 12 | E28: USD per 1M audio tokens out | F28: lanes/g1-gemini-desk/prices.json | G28: 2026-10-19 | H28: read-primary | I28: no announced change for Live
A29: oss_groq_usd_1m | B29: 0.15 | E29: USD per 1M in, gpt-oss-120b on Groq via OpenRouter (cache read 0.075, out 0.60) | F29: lanes/g3-cascade-measured/results/cost_inputs.csv | G29: 2026-10-19 | H29: read-primary
A30: openrouter_fee | B30: 0.055 | E30: OpenRouter platform fee on credit purchases | F30: lanes/g4-market-selfhost/prices.csv / vendor-risk.csv | G30: 2026-10-18 | H30: read-primary | I30: g3 costs did not include it
A31: openrouter_ledger_factor | B31: 1.2 | C31: 1 | D31: 1.45 | E31: OpenRouter account ledger / per-response usage.cost (cancelled streams) | F31: lanes/g3-cascade-measured/verify.md #7 | G31: 2026-10-19 | H31: measured | I31: verifier: model ~1.2x below ledger; ledger windows not fully attributable
A32: gpt41mini_usd_1m | B32: 0.44 | E32: USD per 1M in, gpt-4.1-mini regional South India (cached 0.11, out 1.76); Legacy, retires 2027-04-14 | F32: lanes/g3-cascade-measured/results/cost_inputs.csv | G32: 2026-10-19 | H32: read-primary
A33: gemma4_inworld_usd_1m | B33: 0.07 | E33: USD per 1M in, Gemma 4 26B-A4B on Inworld (out 0.34, no cache price) | F33: lanes/g4-market-selfhost/prices.csv | G33: 2026-10-18 | H33: read-primary
A34: sarvam_stt_inr_min | B34: 0.41 | E34: INR per audio minute, Sarvam real-time STT (Growth/Business), excl. GST | F34: lanes/g4-market-selfhost/prices.csv | G34: 2026-10-18 | H34: read-primary
A35: bulbul_v4f_inr_1k | B35: 1.7 | E35: INR per 1K chars, Sarvam Bulbul V4 Flash (Growth/Business), excl. GST | F35: lanes/g4-market-selfhost/prices.csv | G35: 2026-10-18 | H35: read-primary
A36: inworld_stt_usd_h | B36: 0.1 | E36: USD per audio hour, Inworld STT-1 (paid plans) | F36: lanes/g4-market-selfhost/prices.csv | G36: 2026-10-18 | H36: read-primary
A37: inworld_tts2f_usd_1m | B37: 7 | E37: USD per 1M chars, Inworld TTS-2 Flash (Growth, USD 1,500/month credits); on-demand 15 | F37: lanes/g4-market-selfhost/prices.csv | G37: 2026-10-18 | H37: read-primary
A38: inworld_growth_usd_month | B38: 1500 | E38: USD per month, Inworld Growth plan (credits) | F38: lanes/g4-market-selfhost/prices.csv | G38: 2026-10-18 | H38: read-primary
A39: realtime_mini_inr_min_3 | B39: 1.911 | C39: 1.5 | D39: 6.93 | E39: INR/min, gpt-realtime-2.1-mini 3-min call with prefix caching (no cache 6.93; output cached 1.50) | F39: lanes/g4-market-selfhost/summary.json | G39: 2026-10-18 | H39: computed | I39: desk computation from OpenAI price page; not measured
A40: sh_stt_inr_min_u50 | B40: 0.0467 | E40: INR per connected min, IndicConformer on E2E L4 at 50% utilisation | F40: lanes/g4-market-selfhost/selfhost.csv | G40: 2026-10-18 | H40: computed | I40: throughput vendor-claim/assumed; cost scales as 0.5/util; MC util uniform(0.3,0.7)
...

Sheet Params
A1: name | B1: value | C1: meaning
A2: FX | B2: 95 | C2: INR per USD
A3: EXCH | B3: 5 | C3: exchanges per connected minute
A4: AGENT_S | B4: 24 | C4: agent speech s/min
A5: CALLER_S | B5: 24 | C5: caller speech s/min
A6: GR | B6: 1.186 | C6: gated STT seconds per caller second
A7: TEL | B7: 0.43 | C7: telephony INR per billed minute (0.38-0.48; 1600-series unpublished)
A8: INFRA | B8: 0.03 | C8: orchestration INR per connected minute (assumption 0.01-0.06)
A9: PRICE | B9: 2 | C9: price INR per connected minute
A10: GST_RATE | B10: 0.18 | C10: GST rate
A11: GST_INCL | B11: 0 | C11: 1 if PRICE includes GST, 0 if GST is added on top

Sheet Budget
A1: Allowed AI cost per minute = net price x (1 - margin) - telephony - infra (live formulas on Params)
A3: GST treatment | B3: margin | C3: telephony 0.38 | D3: 0.43 | E3: 0.48 | F3: 1600 sens. 0.60 | G3: 1600 sens. 0.80 | H3: at Params TEL
A4: ex-GST (GST on top) | B4: 0.4 | C4: =ROUND(PRICE*(1-B4)-0.38-INFRA,3) -> 0.79 | D4: =ROUND(PRICE*(1-B4)-0.43-INFRA,3) -> 0.74 | E4: =ROUND(PRICE*(1-B4)-0.48-INFRA,3) -> 0.69 | F4: =ROUND(PRICE*(1-B4)-0.6-INFRA,3) -> 0.57 | G4: =ROUND(PRICE*(1-B4)-0.8-INFRA,3) -> 0.37 | H4: =ROUND(PRICE*(1-B4)-TEL-INFRA,3) -> 0.74
A5: ex-GST (GST on top) | B5: 0.5 | C5: =ROUND(PRICE*(1-B5)-0.38-INFRA,3) -> 0.59 | D5: =ROUND(PRICE*(1-B5)-0.43-INFRA,3) -> 0.54 | E5: =ROUND(PRICE*(1-B5)-0.48-INFRA,3) -> 0.49 | F5: =ROUND(PRICE*(1-B5)-0.6-INFRA,3) -> 0.37 | G5: =ROUND(PRICE*(1-B5)-0.8-INFRA,3) -> 0.17 | H5: =ROUND(PRICE*(1-B5)-TEL-INFRA,3) -> 0.54
A6: ex-GST (GST on top) | B6: 0.6 | C6: =ROUND(PRICE*(1-B6)-0.38-INFRA,3) -> 0.39 | D6: =ROUND(PRICE*(1-B6)-0.43-INFRA,3) -> 0.34 | E6: =ROUND(PRICE*(1-B6)-0.48-INFRA,3) -> 0.29 | F6: =ROUND(PRICE*(1-B6)-0.6-INFRA,3) -> 0.17 | G6: =ROUND(PRICE*(1-B6)-0.8-INFRA,3) -> -0.03 | H6: =ROUND(PRICE*(1-B6)-TEL-INFRA,3) -> 0.34
A7: GST-inclusive | B7: 0.4 | C7: =ROUND(PRICE/(1+GST_RATE)*(1-B7)-0.38-INFRA,3) -> 0.607 | D7: =ROUND(PRICE/(1+GST_RATE)*(1-B7)-0.43-INFRA,3) -> 0.557 | E7: =ROUND(PRICE/(1+GST_RATE)*(1-B7)-0.48-INFRA,3) -> 0.507 | F7: =ROUND(PRICE/(1+GST_RATE)*(1-B7)-0.6-INFRA,3) -> 0.387 | G7: =ROUND(PRICE/(1+GST_RATE)*(1-B7)-0.8-INFRA,3) -> 0.187 | H7: =ROUND(PRICE/(1+GST_RATE)*(1-B7)-TEL-INFRA,3) -> 0.557
A8: GST-inclusive | B8: 0.5 | C8: =ROUND(PRICE/(1+GST_RATE)*(1-B8)-0.38-INFRA,3) -> 0.437 | D8: =ROUND(PRICE/(1+GST_RATE)*(1-B8)-0.43-INFRA,3) -> 0.387 | E8: =ROUND(PRICE/(1+GST_RATE)*(1-B8)-0.48-INFRA,3) -> 0.337 | F8: =ROUND(PRICE/(1+GST_RATE)*(1-B8)-0.6-INFRA,3) -> 0.217 | G8: =ROUND(PRICE/(1+GST_RATE)*(1-B8)-0.8-INFRA,3) -> 0.017 | H8: =ROUND(PRICE/(1+GST_RATE)*(1-B8)-TEL-INFRA,3) -> 0.387
A9: GST-inclusive | B9: 0.6 | C9: =ROUND(PRICE/(1+GST_RATE)*(1-B9)-0.38-INFRA,3) -> 0.268 | D9: =ROUND(PRICE/(1+GST_RATE)*(1-B9)-0.43-INFRA,3) -> 0.218 | E9: =ROUND(PRICE/(1+GST_RATE)*(1-B9)-0.48-INFRA,3) -> 0.168 | F9: =ROUND(PRICE/(1+GST_RATE)*(1-B9)-0.6-INFRA,3) -> 0.048 | G9: =ROUND(PRICE/(1+GST_RATE)*(1-B9)-0.8-INFRA,3) -> -0.152 | H9: =ROUND(PRICE/(1+GST_RATE)*(1-B9)-TEL-INFRA,3) -> 0.218
A11: Price needed for a given AI cost: (AI + TEL + INFRA) / (1 - margin), ex-GST | C11: price at 40% | D11: price at 50% | E11: price at 60%
A12: AI cost INR/min | B12: 0.94 | C12: =ROUND((B12+TEL+INFRA)/(1-0.4),3) -> 2.333 | D12: =ROUND((B12+TEL+INFRA)/(1-0.5),3) -> 2.8 | E12: =ROUND((B12+TEL+INFRA)/(1-0.6),3) -> 3.5

Sheet Calc
A1: id | B1: name | C1: L_min | D1: stt_mode | E1: stt_usd_per_s | F1: stt_inr_per_s | G1: stt_text_tok_per_exch | H1: stt_text_usd_per_tok | I1: stt_fixed_inr | J1: llm_in_usd_1m | K1: llm_cached_usd_1m | L1: llm_out_usd_1m | M1: cache_share | N1: P0_tok | O1: growth_tok_per_exch | P1: waste | Q1: out_tok_per_exch | R1: llm_fee_x_ledger | S1: s_extra_tok | T1: tts_usd_per_agent_s | U1: tts_inr_per_agent_s | V1: tts_lead_s | W1: tts_text_tok_per_exch | X1: tts_text_usd_per_tok | Y1: tts_fixed_inr | Z1: learn | AA1: STT | AB1: LLM | AC1: TTS | AD1: LEARN | AE1: AI | AF1: TEL_per_min | AG1: COGS | AH1: price_at_40 | AI1: price_at_50 | AJ1: price_at_60 | AK1: margin_at_PRICE | AL1: python_ai | AM1: diff
A2: C1 | B2: Azure STT + gpt-4.1-mini (South India) + Azure neural | C2: 1 | D2: full | E2: 0.00027777778 | F2: 0 | G2: 0 | H2: 0 | I2: 0 | J2: 0.44 | K2: 0.11 | L2: 1.76 | M2: 0.94 | N2: 1727 | O2: 51.3 | P2: 1.842 | Q2: 28.6 | R2: 1 | S2: 0 | T2: 0.00015045 | U2: 0 | V2: 0 | W2: 0 | X2: 0 | Y2: 0 | Z2: 0 | AA2: =IF(D2="full",60,IF(D2="gated",CALLER_S*GR,0))*(E2*FX+F2)+EXCH*G2*H2*FX+I2 -> 1.5833333 | AB2: =EXCH*R2*((N2+S2+O2*(MAX(EXCH*C2,1)-1)/2)*P2*((1-M2)*J2+M2*K2)+Q2*L2)/1000000*FX -> 0.23169455 | AC2: =(AGENT_S+V2*EXCH)*(T2*FX+U2)+EXCH*W2*X2*FX+Y2 -> 0.343026 | AD2: =IF(Z2=1,((214*C2+S2+1000)*0.44+400*1.76)/1000000*FX/C2,0) -> 0 | AE2: =AA2+AB2+AC2+AD2 -> 2.1580539 | AF2: =TEL*(C2+0.25)/C2 -> 0.5375 | AG2: =AE2+AF2+INFRA -> 2.7255539 | AH2: =AG2/0.6 -> 4.5425898 | AI2: =AG2/0.5 -> 5.4511078 | AJ2: =AG2/0.4 -> 6.8138847 | AK2: =1-AG2/IF(GST_INCL=1,PRICE/(1+GST_RATE),PRICE) -> -0.36277694 | AL2: 2.158054 | AM2: =AE2-AL2 -> -1.2077067e-07
A3: C1 | B3: Azure STT + gpt-4.1-mini (South India) + Azure neural | C3: 3 | D3: full | E3: 0.00027777778 | F3: 0 | G3: 0 | H3: 0 | I3: 0 | J3: 0.44 | K3: 0.11 | L3: 1.76 | M3: 0.94 | N3: 1727 | O3: 51.3 | P3: 1.842 | Q3: 28.6 | R3: 1 | S3: 0 | T3: 0.00015045 | U3: 0 | V3: 0 | W3: 0 | X3: 0 | Y3: 0 | Z3: 0 | AA3: =IF(D3="full",60,IF(D3="gated",CALLER_S*GR,0))*(E3*FX+F3)+EXCH*G3*H3*FX+I3 -> 1.5833333 | AB3: =EXCH*R3*((N3+S3+O3*(MAX(EXCH*C3,1)-1)/2)*P3*((1-M3)*J3+M3*K3)+Q3*L3)/1000000*FX -> 0.26082487 | AC3: =(AGENT_S+V3*EXCH)*(T3*FX+U3)+EXCH*W3*X3*FX+Y3 -> 0.343026 | AD3: =IF(Z3=1,((214*C3+S3+1000)*0.44+400*1.76)/1000000*FX/C3,0) -> 0 | AE3: =AA3+AB3+AC3+AD3 -> 2.1871842 | AF3: =TEL*(C3+0.25)/C3 -> 0.46583333 | AG3: =AE3+AF3+INFRA -> 2.6830175 | AH3: =AG3/0.6 -> 4.4716959 | AI3: =AG3/0.5 -> 5.3660351 | AJ3: =AG3/0.4 -> 6.7075438 | AK3: =1-AG3/IF(GST_INCL=1,PRICE/(1+GST_RATE),PRICE) -> -0.34150877 | AL3: 2.187184 | AM3: =AE3-AL3 -> 2.0204433e-07
A4: C1 | B4: Azure STT + gpt-4.1-mini (South India) + Azure neural | C4: 5 | D4: full | E4: 0.00027777778 | F4: 0 | G4: 0 | H4: 0 | I4: 0 | J4: 0.44 | K4: 0.11 | L4: 1.76 | M4: 0.94 | N4: 1727 | O4: 51.3 | P4: 1.842 | Q4: 28.6 | R4: 1 | S4: 0 | T4: 0.00015045 | U4: 0 | V4: 0 | W4: 0 | X4: 0 | Y4: 0 | Z4: 0 | AA4: =IF(D4="full",60,IF(D4="gated",CALLER_S*GR,0))*(E4*FX+F4)+EXCH*G4*H4*FX+I4 -> 1.5833333 | AB4: =EXCH*R4*((N4+S4+O4*(MAX(EXCH*C4,1)-1)/2)*P4*((1-M4)*J4+M4*K4)+Q4*L4)/1000000*FX -> 0.28995519 | AC4: =(AGENT_S+V4*EXCH)*(T4*FX+U4)+EXCH*W4*X4*FX+Y4 -> 0.343026 | AD4: =IF(Z4=1,((214*C4+S4+1000)*0.44+400*1.76)/1000000*FX/C4,0) -> 0 | AE4: =AA4+AB4+AC4+AD4 -> 2.2163145 | AF4: =TEL*(C4+0.25)/C4 -> 0.4515 | AG4: =AE4+AF4+INFRA -> 2.6978145 | AH4: =AG4/0.6 -> 4.4963575 | AI4: =AG4/0.5 -> 5.395629 | AJ4: =AG4/0.4 -> 6.7445363 | AK4: =1-AG4/IF(GST_INCL=1,PRICE/(1+GST_RATE),PRICE) -> -0.34890726 | AL4: 2.216315 | AM4: =AE4-AL4 -> -4.7514067e-07
A5: C1 | B5: Azure STT + gpt-4.1-mini (South India) + Azure neural | C5: 10 | D5: full | E5: 0.00027777778 | F5: 0 | G5: 0 | H5: 0 | I5: 0 | J5: 0.44 | K5: 0.11 | L5: 1.76 | M5: 0.94 | N5: 1727 | O5: 51.3 | P5: 1.842 | Q5: 28.6 | R5: 1 | S5: 0 | T5: 0.00015045 | U5: 0 | V5: 0 | W5: 0 | X5: 0 | Y5: 0 | Z5: 0 | AA5: =IF(D5="full",60,IF(D5="gated",CALLER_S*GR,0))*(E5*FX+F5)+EXCH*G5*H5*FX+I5 -> 1.5833333 | AB5: =EXCH*R5*((N5+S5+O5*(MAX(EXCH*C5,1)-1)/2)*P5*((1-M5)*J5+M5*K5)+Q5*L5)/1000000*FX -> 0.362781 | AC5: =(AGENT_S+V5*EXCH)*(T5*FX+U5)+EXCH*W5*X5*FX+Y5 -> 0.343026 | AD5: =IF(Z5=1,((214*C5+S5+1000)*0.44+400*1.76)/1000000*FX/C5,0) -> 0 | AE5: =AA5+AB5+AC5+AD5 -> 2.2891403 | AF5: =TEL*(C5+0.25)/C5 -> 0.44075 | AG5: =AE5+AF5+INFRA -> 2.7598903 | AH5: =AG5/0.6 -> 4.5998172 | AI5: =AG5/0.5 -> 5.5197807 | AJ5: =AG5/0.4 -> 6.8997258 | AK5: =1-AG5/IF(GST_INCL=1,PRICE/(1+GST_RATE),PRICE) -> -0.37994517 | AL5: 2.28914 | AM5: =AE5-AL5 -> 3.3189683e-07
A6: C1g | B6: C1 with VAD-gated STT | C6: 1 | D6: gated | E6: 0.00027777778 | F6: 0 | G6: 0 | H6: 0 | I6: 0 | J6: 0.44 | K6: 0.11 | L6: 1.76 | M6: 0.94 | N6: 1727 | O6: 51.3 | P6: 1.842 | Q6: 28.6 | R6: 1 | S6: 0 | T6: 0.00015045 | U6: 0 | V6: 0 | W6: 0 | X6: 0 | Y6: 0 | Z6: 0 | AA6: =IF(D6="full",60,IF(D6="gated",CALLER_S*GR,0))*(E6*FX+F6)+EXCH*G6*H6*FX+I6 -> 0.75113333 | AB6: =EXCH*R6*((N6+S6+O6*(MAX(EXCH*C6,1)-1)/2)*P6*((1-M6)*J6+M6*K6)+Q6*L6)/1000000*FX -> 0.23169455 | AC6: =(AGENT_S+V6*EXCH)*(T6*FX+U6)+EXCH*W6*X6*FX+Y6 -> 0.343026 | AD6: =IF(Z6=1,((214*C6+S6+1000)*0.44+400*1.76)/1000000*FX/C6,0) -> 0 | AE6: =AA6+AB6+AC6+AD6 -> 1.3258539 | AF6: =TEL*(C6+0.25)/C6 -> 0.5375 | AG6: =AE6+AF6+INFRA -> 1.8933539 | AH6: =AG6/0.6 -> 3.1555898 | AI6: =AG6/0.5 -> 3.7867078 | AJ6: =AG6/0.4 -> 4.7333847 | AK6: =1-AG6/IF(GST_INCL=1,PRICE/(1+GST_RATE),PRICE) -> 0.05332306 | AL6: 1.325854 | AM6: =AE6-AL6 -> -1.2077067e-07
A7: C1g | B7: C1 with VAD-gated STT | C7: 3 | D7: gated | E7: 0.00027777778 | F7: 0 | G7: 0 | H7: 0 | I7: 0 | J7: 0.44 | K7: 0.11 | L7: 1.76 | M7: 0.94 | N7: 1727 | O7: 51.3 | P7: 1.842 | Q7: 28.6 | R7: 1 | S7: 0 | T7: 0.00015045 | U7: 0 | V7: 0 | W7: 0 | X7: 0 | Y7: 0 | Z7: 0 | AA7: =IF(D7="full",60,IF(D7="gated",CALLER_S*GR,0))*(E7*FX+F7)+EXCH*G7*H7*FX+I7 -> 0.75113333 | AB7: =EXCH*R7*((N7+S7+O7*(MAX(EXCH*C7,1)-1)/2)*P7*((1-M7)*J7+M7*K7)+Q7*L7)/1000000*FX -> 0.26082487 | AC7: =(AGENT_S+V7*EXCH)*(T7*FX+U7)+EXCH*W7*X7*FX+Y7 -> 0.343026 | AD7: =IF(Z7=1,((214*C7+S7+1000)*0.44+400*1.76)/1000000*FX/C7,0) -> 0 | AE7: =AA7+AB7+AC7+AD7 -> 1.3549842 | AF7: =TEL*(C7+0.25)/C7 -> 0.46583333 | AG7: =AE7+AF7+INFRA -> 1.8508175 | AH7: =AG7/0.6 -> 3.0846959 | AI7: =AG7/0.5 -> 3.7016351 | AJ7: =AG7/0.4 -> 4.6270438 | AK7: =1-AG7/IF(GST_INCL=1,PRICE/(1+GST_RATE),PRICE) -> 0.074591232 | AL7: 1.354984 | AM7: =AE7-AL7 -> 2.0204433e-07
A8: C1g | B8: C1 with VAD-gated STT | C8: 5 | D8: gated | E8: 0.00027777778 | F8: 0 | G8: 0 | H8: 0 | I8: 0 | J8: 0.44 | K8: 0.11 | L8: 1.76 | M8: 0.94 | N8: 1727 | O8: 51.3 | P8: 1.842 | Q8: 28.6 | R8: 1 | S8: 0 | T8: 0.00015045 | U8: 0 | V8: 0 | W8: 0 | X8: 0 | Y8: 0 | Z8: 0 | AA8: =IF(D8="full",60,IF(D8="gated",CALLER_S*GR,0))*(E8*FX+F8)+EXCH*G8*H8*FX+I8 -> 0.75113333 | AB8: =EXCH*R8*((N8+S8+O8*(MAX(EXCH*C8,1)-1)/2)*P8*((1-M8)*J8+M8*K8)+Q8*L8)/1000000*FX -> 0.28995519 | AC8: =(AGENT_S+V8*EXCH)*(T8*FX+U8)+EXCH*W8*X8*FX+Y8 -> 0.343026 | AD8: =IF(Z8=1,((214*C8+S8+1000)*0.44+400*1.76)/1000000*FX/C8,0) -> 0 | AE8: =AA8+AB8+AC8+AD8 -> 1.3841145 | AF8: =TEL*(C8+0.25)/C8 -> 0.4515 | AG8: =AE8+AF8+INFRA -> 1.8656145 | AH8: =AG8/0.6 -> 3.1093575 | AI8: =AG8/0.5 -> 3.731229 | AJ8: =AG8/0.4 -> 4.6640363 | AK8: =1-AG8/IF(GST_INCL=1,PRICE/(1+GST_RATE),PRICE) -> 0.067192738 | AL8: 1.384115 | AM8: =AE8-AL8 -> -4.7514067e-07
A9: C1g | B9: C1 with VAD-gated STT | C9: 10 | D9: gated | E9: 0.00027777778 | F9: 0 | G9: 0 | H9: 0 | I9: 0 | J9: 0.44 | K9: 0.11 | L9: 1.76 | M9: 0.94 | N9: 1727 | O9: 51.3 | P9: 1.842 | Q9: 28.6 | R9: 1 | S9: 0 | T9: 0.00015045 | U9: 0 | V9: 0 | W9: 0 | X9: 0 | Y9: 0 | Z9: 0 | AA9: =IF(D9="full",60,IF(D9="gated",CALLER_S*GR,0))*(E9*FX+F9)+EXCH*G9*H9*FX+I9 -> 0.75113333 | AB9: =EXCH*R9*((N9+S9+O9*(MAX(EXCH*C9,1)-1)/2)*P9*((1-M9)*J9+M9*K9)+Q9*L9)/1000000*FX -> 0.362781 | AC9: =(AGENT_S+V9*EXCH)*(T9*FX+U9)+EXCH*W9*X9*FX+Y9 -> 0.343026 | AD9: =IF(Z9=1,((214*C9+S9+1000)*0.44+400*1.76)/1000000*FX/C9,0) -> 0 | AE9: =AA9+AB9+AC9+AD9 -> 1.4569403 | AF9: =TEL*(C9+0.25)/C9 -> 0.44075 | AG9: =AE9+AF9+INFRA -> 1.9276903 | AH9: =AG9/0.6 -> 3.2128172 | AI9: =AG9/0.5 -> 3.8553807 | AJ9: =AG9/0.4 -> 4.8192258 | AK9: =1-AG9/IF(GST_INCL=1,PRICE/(1+GST_RATE),PRICE) -> 0.036154834 | AL9: 1.45694 | AM9: =AE9-AL9 -> 3.3189683e-07
A10: C2 | B10: Azure STT + gpt-4.1-mini + Azure DragonHD | C10: 1 | D10: full | E10: 0.00027777778 | F10: 0 | G10: 0 | H10: 0 | I10: 0 | J10: 0.44 | K10: 0.11 | L10: 1.76 | M10: 0.948 | N10: 1725 | O10: 52.7 | P10: 1.841 | Q10: 30.4 | R10: 1 | S10: 0 | T10: 0.00037796 | U10: 0 | V10: 0 | W10: 0 | X10: 0 | Y10: 0 | Z10: 0 | AA10: =IF(D10="full",60,IF(D10="gated",CALLER_S*GR,0))*(E10*FX+F10)+EXCH*G10*H10*FX+I10 -> 1.5833333 | AB10: =EXCH*R10*((N10+S10+O10*(MAX(EXCH*C10,1)-1)/2)*P10*((1-M10)*J10+M10*K10)+Q10*L10)/1000000*FX -> 0.22895166 | AC10: =(AGENT_S+V10*EXCH)*(T10*FX+U10)+EXCH*W10*X10*FX+Y10 -> 0.8617488 | AD10: =IF(Z10=1,((214*C10+S10+1000)*0.44+400*1.76)/1000000*FX/C10,0) -> 0 | AE10: =AA10+AB10+AC10+AD10 -> 2.6740338 | AF10: =TEL*(C10+0.25)/C10 -> 0.5375 | AG10: =AE10+AF10+INFRA -> 3.2415338 | AH10: =AG10/0.6 -> 5.4025563 | AI10: =AG10/0.5 -> 6.4830676 | AJ10: =AG10/0.4 -> 8.1038345 | AK10: =1-AG10/IF(GST_INCL=1,PRICE/(1+GST_RATE),PRICE) -> -0.6207669 | AL10: 2.674034 | AM10: =AE10-AL10 -> -2.0634027e-07
A11: C2 | B11: Azure STT + gpt-4.1-mini + Azure DragonHD | C11: 3 | D11: full | E11: 0.00027777778 | F11: 0 | G11: 0 | H11: 0 | I11: 0 | J11: 0.44 | K11: 0.11 | L11: 1.76 | M11: 0.948 | N11: 1725 | O11: 52.7 | P11: 1.841 | Q11: 30.4 | R11: 1 | S11: 0 | T11: 0.00037796 | U11: 0 | V11: 0 | W11: 0 | X11: 0 | Y11: 0 | Z11: 0 | AA11: =IF(D11="full",60,IF(D11="gated",CALLER_S*GR,0))*(E11*FX+F11)+EXCH*G11*H11*FX+I11 -> 1.5833333 | AB11: =EXCH*R11*((N11+S11+O11*(MAX(EXCH*C11,1)-1)/2)*P11*((1-M11)*J11+M11*K11)+Q11*L11)/1000000*FX -> 0.2582524 | AC11: =(AGENT_S+V11*EXCH)*(T11*FX+U11)+EXCH*W11*X11*FX+Y11 -> 0.8617488 | AD11: =IF(Z11=1,((214*C11+S11+1000)*0.44+400*1.76)/1000000*FX/C11,0) -> 0 | AE11: =AA11+AB11+AC11+AD11 -> 2.7033345 | AF11: =TEL*(C11+0.25)/C11 -> 0.46583333 | AG11: =AE11+AF11+INFRA -> 3.1991679 | AH11: =AG11/0.6 -> 5.3319464 | AI11: =AG11/0.5 -> 6.3983357 | AJ11: =AG11/0.4 -> 7.9979197 | AK11: =1-AG11/IF(GST_INCL=1,PRICE/(1+GST_RATE),PRICE) -> -0.59958393 | AL11: 2.703335 | AM11: =AE11-AL11 -> -4.6983677e-07
A12: C2 | B12: Azure STT + gpt-4.1-mini + Azure DragonHD | C12: 5 | D12: full | E12: 0.00027777778 | F12: 0 | G12: 0 | H12: 0 | I12: 0 | J12: 0.44 | K12: 0.11 | L12: 1.76 | M12: 0.948 | N12: 1725 | O12: 52.7 | P12: 1.841 | Q12: 30.4 | R12: 1 | S12: 0 | T12: 0.00037796 | U12: 0 | V12: 0 | W12: 0 | X12: 0 | Y12: 0 | Z12: 0 | AA12: =IF(D12="full",60,IF(D12="gated",CALLER_S*GR,0))*(E12*FX+F12)+EXCH*G12*H12*FX+I12 -> 1.5833333 | AB12: =EXCH*R12*((N12+S12+O12*(MAX(EXCH*C12,1)-1)/2)*P12*((1-M12)*J12+M12*K12)+Q12*L12)/1000000*FX -> 0.28755313 | AC12: =(AGENT_S+V12*EXCH)*(T12*FX+U12)+EXCH*W12*X12*FX+Y12 -> 0.8617488 | AD12: =IF(Z12=1,((214*C12+S12+1000)*0.44+400*1.76)/1000000*FX/C12,0) -> 0 | AE12: =AA12+AB12+AC12+AD12 -> 2.7326353 | AF12: =TEL*(C12+0.25)/C12 -> 0.4515 | AG12: =AE12+AF12+INFRA -> 3.2141353 | AH12: =AG12/0.6 -> 5.3568921 | AI12: =AG12/0.5 -> 6.4282705 | AJ12: =AG12/0.4 -> 8.0353382 | AK12: =1-AG12/IF(GST_INCL=1,PRICE/(1+GST_RATE),PRICE) -> -0.60706763 | AL12: 2.732635 | AM12: =AE12-AL12 -> 2.6666673e-07
A13: C2 | B13: Azure STT + gpt-4.1-mini + Azure DragonHD | C13: 10 | D13: full | E13: 0.00027777778 | F13: 0 | G13: 0 | H13: 0 | I13: 0 | J13: 0.44 | K13: 0.11 | L13: 1.76 | M13: 0.948 | N13: 1725 | O13: 52.7 | P13: 1.841 | Q13: 30.4 | R13: 1 | S13: 0 | T13: 0.00037796 | U13: 0 | V13: 0 | W13: 0 | X13: 0 | Y13: 0 | Z13: 0 | AA13: =IF(D13="full",60,IF(D13="gated",CALLER_S*GR,0))*(E13*FX+F13)+EXCH*G13*H13*FX+I13 -> 1.5833333 | AB13: =EXCH*R13*((N13+S13+O13*(MAX(EXCH*C13,1)-1)/2)*P13*((1-M13)*J13+M13*K13)+Q13*L13)/1000000*FX -> 0.36080497 | AC13: =(AGENT_S+V13*EXCH)*(T13*FX+U13)+EXCH*W13*X13*FX+Y13 -> 0.8617488 | AD13: =IF(Z13=1,((214*C13+S13+1000)*0.44+400*1.76)/1000000*FX/C13,0) -> 0 | AE13: =AA13+AB13+AC13+AD13 -> 2.8058871 | AF13: =TEL*(C13+0.25)/C13 -> 0.44075 | AG13: =AE13+AF13+INFRA -> 3.2766371 | AH13: =AG13/0.6 -> 5.4610618 | AI13: =AG13/0.5 -> 6.5532742 | AJ13: =AG13/0.4 -> 8.1915928 | AK13: =1-AG13/IF(GST_INCL=1,PRICE/(1+GST_RATE),PRICE) -> -0.63831855 | AL13: 2.805887 | AM13: =AE13-AL13 -> 1.0792548e-07
... A77: tier:premium | B77: India-processed: Azure STT gated (Central India) + gpt-4.1-mini (South India) + Azure Custom Neural Voice; ~10k-token personal memory | C77: 10 | D77: gated | E77: 0.00027777778 | F77: 0 | G77: 0 | H77: 0 | I77: 0 | J77: 0.44 | K77: 0.11 | L77: 1.76 | M77: 0.94 | N77: 1727 | O77: 51.3 | P77: 1.842 | Q77: 28.6 | R77: 1 | S77: 10000 | T77: 0.00024072 | U77: 0 | V77: 0 | W77: 0 | X77: 0 | Y77: 0 | Z77: 1 | AA77: =IF(D77="full",60,IF(D77="gated",CALLER_S*GR,0))*(E77*FX+F77)+EXCH*G77*H77*FX+I77 -> 0.75113333 | AB77: =EXCH*R77*((N77+S77+O77*(MAX(EXCH*C77,1)-1)/2)*P77*((1-M77)*J77+M77*K77)+Q77*L77)/1000000*FX -> 1.4984661 | AC77: =(AGENT_S+V77*EXCH)*(T77*FX+U77)+EXCH*W77*X77*FX+Y77 -> 0.5488416 | AD77: =IF(Z77=1,((214*C77+S77+1000)*0.44+400*1.76)/1000000*FX/C77,0) -> 0.0616132 | AE77: =AA77+AB77+AC77+AD77 -> 2.8600542 | AF77: =TEL*(C77+0.25)/C77 -> 0.44075 | AG77: =AE77+AF77+INFRA -> 3.3308042 | AH77: =AG77/0.6 -> 5.5513404 | AI77: =AG77/0.5 -> 6.6616085 | AJ77: =AG77/0.4 -> 8.3270106 | AK77: =1-AG77/IF(GST_INCL=1,PRICE/(1+GST_RATE),PRICE) -> -0.66540212 | AL77: 2.860054 | AM77: =AE77-AL77 -> 2.3189683e-07

Sheet Tiers
A1: tier | B1: stack | C1: price ex-GST (edit) | D1: price incl. GST | E1: AI 3-min (Calc) | F1: COGS 3-min (Calc) | G1: margin 3-min (formula) | H1: MC AI minute-weighted | I1: MC COGS minute-weighted | J1: MC margin minute-weighted | K1: MC P(call margin>=40%) | L1: price for 40% (MC) | M1: price for 50% (MC) | N1: dedicated-voice fee INR/month
A2: base | B2: C6g: gated gemini-3.5-transcribe-live + gpt-oss-120b on Groq + Azure neural stock voice; persona + light memory | C2: 2.99 | D2: =ROUND(C2*(1+GST_RATE),2) -> 3.53 | E2: =Calc!AE63 -> 1.0342052 | F2: =Calc!AG63 -> 1.5300386 | G2: =1-F2/C2 -> 0.48828141 | H2: 1.219 | I2: 1.715 | J2: 0.426 | K2: 0.697 | L2: 2.858 | M2: 3.43 | N2: 0
A3: base-HD | B3: base with Azure DragonHD voice (the fallback if the panel rejects the neural voice) | C3: 3.49 | D3: =ROUND(C3*(1+GST_RATE),2) -> 4.12 | E3: =Calc!AE67 -> 1.565582 | F3: =Calc!AG67 -> 2.0614154 | G3: =1-F3/C3 -> 0.40933657 | H3: 1.764 | I3: 2.259 | J3: 0.353 | K3: 0.242 | L3: 3.766 | M3: 4.519 | N3: 0
A4: plus | B4: base + learned memory in context (~4k tokens) + post-call learning pass (gpt-4.1-mini South India) | C4: 3.99 | D4: =ROUND(C4*(1+GST_RATE),2) -> 4.71 | E4: =Calc!AE71 -> 1.4138574 | F4: =Calc!AG71 -> 1.9096907 | G4: =1-F4/C4 -> 0.52138076 | H4: 1.646 | I4: 2.142 | J4: 0.463 | K4: 0.767 | L4: 3.57 | M4: 4.284 | N4: 0
A5: premium | B5: India-processed: Azure STT gated (Central India) + gpt-4.1-mini (South India) + Azure Custom Neural Voice; ~10k-token personal memory | C5: 6.49 | D5: =ROUND(C5*(1+GST_RATE),2) -> 7.66 | E5: =Calc!AE75 -> 2.8809901 | F5: =Calc!AG75 -> 3.3768234 | G5: =1-F5/C5 -> 0.47968822 | H5: 3.023 | I5: 3.519 | J5: 0.458 | K5: 0.725 | L5: 5.864 | M5: 7.037 | N5: 350000

Sheet Live_g5
A1: Gemini Live AI cost, INR per connected minute, g5 paid meter (lanes/g5-gemini-paid/results/cost_per_minute_summary.csv), n=1-2 calls per cell
A2: model | B2: compression | C2: 1 min | D2: 3 min | E2: 5 min | F2: 10 min | G2: 10 min / 1 min
A3: 3.1 | B3: off | C3: 2.47 | D3: 4.71 | E3: 6.85 | F3: 10.74 | G3: 4.35
A4: 3.1 | B4: on6k | C4: 2.55 | D4: 4.19 | E4: 5.34 | F4: 6.38 | G4: 2.5
A5: 3.8 | B5: off | C5: 3.31 | D5: 5.72 | E5: 8.05 | F5: 12.7 | G5: 3.84
A6: 3.8 | B6: on6k | C6: 3.34 | D6: 5.72 | E6: 7.94 | F6: 9.05 | G6: 2.71
A8: Tight compression (trigger 2500 / target 1500), 10 min: 3.1 2.85, 3.8 3.68; keeps ~17-27 s of audio history, so the agent forgets the call (g5).
A9: Modelled at the reference workload and MC ranges: see MC sheet rows L31, L38, L38c. Model vs meter: see Calibration.

Sheet MC
A1: stack | B1: price_regime | C1: call_min | D1: ai_p10 | E1: ai_p50 | F1: ai_p90 | G1: ai_mean | H1: cogs_p50 | I1: ai_call_p50 | J1: p_ai_within_budget_50pct | K1: p_margin_ge_40_at_inr2 | L1: note
A2: C1 | B2: 2026 | C2: 1 | D2: 2.058 | E2: 2.188 | F2: 2.331 | G2: 2.192 | H2: 2.76 | I2: 2.188 | J2: 0 | K2: 0
A3: C1 | B3: 2026 | C3: 3 | D3: 2.083 | E3: 2.219 | F3: 2.369 | G3: 2.223 | H3: 2.719 | I3: 6.657 | J3: 0 | K3: 0
A4: C1 | B4: 2026 | C4: 5 | D4: 2.107 | E4: 2.251 | F4: 2.407 | G4: 2.255 | H4: 2.737 | I4: 11.253 | J4: 0 | K4: 0
A5: C1 | B5: 2026 | C5: 10 | D5: 2.164 | E5: 2.328 | F5: 2.507 | G5: 2.333 | H5: 2.803 | I5: 23.285 | J5: 0 | K5: 0
A6: C1 | B6: 2026 | C6: mix-short | E6: 2.264 | G6: 2.264 | H6: 2.76 | I6: 5.569 | L6: minute-weighted mean over the call-length mix
A7: C1 | B7: 2026 | C7: mix-companion | E7: 2.387 | G7: 2.387 | H7: 2.861 | I7: 18.423 | L7: minute-weighted mean over the call-length mix
A8: C1g | B8: 2026 | C8: 1 | D8: 1.117 | E8: 1.332 | F8: 1.534 | G8: 1.329 | H8: 1.903 | I8: 1.332 | J8: 0 | K8: 0
A9: C1g | B9: 2026 | C9: 3 | D9: 1.146 | E9: 1.363 | F9: 1.569 | G9: 1.36 | H9: 1.862 | I9: 4.089 | J9: 0 | K9: 0
A10: C1g | B10: 2026 | C10: 5 | D10: 1.174 | E10: 1.394 | F10: 1.605 | G10: 1.392 | H10: 1.879 | I10: 6.971 | J10: 0 | K10: 0
A11: C1g | B11: 2026 | C11: 10 | D11: 1.239 | E11: 1.472 | F11: 1.699 | G11: 1.47 | H11: 1.946 | I11: 14.72 | J11: 0 | K11: 0
A12: C1g | B12: 2026 | C12: mix-short | E12: 1.401 | G12: 1.401 | H12: 1.897 | I12: 3.382 | L12: minute-weighted mean over the call-length mix
A13: C1g | B13: 2026 | C13: mix-companion | E13: 1.524 | G13: 1.524 | H13: 1.999 | I13: 11.438 | L13: minute-weighted mean over the call-length mix
A14: C2 | B14: 2026 | C14: 1 | D14: 2.471 | E14: 2.712 | F14: 2.979 | G14: 2.719 | H14: 3.283 | I14: 2.712 | J14: 0 | K14: 0
A15: C2 | B15: 2026 | C15: 3 | D15: 2.5 | E15: 2.744 | F15: 3.013 | G15: 2.75 | H15: 3.242 | I15: 8.232 | J15: 0 | K15: 0
A16: C2 | B16: 2026 | C16: 5 | D16: 2.527 | E16: 2.775 | F16: 3.049 | G16: 2.782 | H16: 3.26 | I16: 13.876 | J16: 0 | K16: 0
A17: C2 | B17: 2026 | C17: 10 | D17: 2.595 | E17: 2.854 | F17: 3.138 | G17: 2.861 | H17: 3.328 | I17: 28.541 | J17: 0 | K17: 0
A18: C2 | B18: 2026 | C18: mix-short | E18: 2.792 | G18: 2.792 | H18: 3.287 | I18: 6.889 | L18: minute-weighted mean over the call-length mix
A19: C2 | B19: 2026 | C19: mix-companion | E19: 2.915 | G19: 2.915 | H19: 3.389 | I19: 22.625 | L19: minute-weighted mean over the call-length mix
A20: C3 | B20: 2026 | C20: 1 | D20: 2.451 | E20: 2.693 | F20: 2.959 | G20: 2.698 | H20: 3.264 | I20: 2.693 | J20: 0 | K20: 0
A21: C3 | B21: 2026 | C21: 3 | D21: 2.483 | E21: 2.728 | F21: 2.999 | G21: 2.734 | H21: 3.227 | I21: 8.185 | J21: 0 | K21: 0
A22: C3 | B22: 2026 | C22: 5 | D22: 2.513 | E22: 2.764 | F22: 3.038 | G22: 2.77 | H22: 3.248 | I22: 13.82 | J22: 0 | K22: 0
A23: C3 | B23: 2026 | C23: 10 | D23: 2.586 | E23: 2.851 | F23: 3.14 | G23: 2.858 | H23: 3.325 | I23: 28.506 | J23: 0 | K23: 0
A24: C3 | B24: 2026 | C24: mix-short | E24: 2.78 | G24: 2.78 | H24: 3.276 | I24: 6.849 | L24: minute-weighted mean over the call-length mix
A25: C3 | B25: 2026 | C25: mix-companion | E25: 2.919 | G25: 2.919 | H25: 3.393 | I25: 22.559 | L25: minute-weighted mean over the call-length mix
A26: C6 | B26: 2026 | C26: 1 | D26: 1.185 | E26: 1.33 | F26: 1.48 | G26: 1.331 | H26: 1.902 | I26: 1.33 | J26: 0 | K26: 0
A27: C6 | B27: 2026 | C27: 3 | D27: 1.21 | E27: 1.364 | F27: 1.522 | G27: 1.365 | H27: 1.863 | I27: 4.091 | J27: 0 | K27: 0
A28: C6 | B28: 2026 | C28: 5 | D28: 1.235 | E28: 1.397 | F28: 1.565 | G28: 1.399 | H28: 1.882 | I28: 6.986 | J28: 0 | K28: 0
A29: C6 | B29: 2026 | C29: 10 | D29: 1.294 | E29: 1.479 | F29: 1.676 | G29: 1.483 | H29: 1.954 | I29: 14.792 | J29: 0 | K29: 0
A30: C6 | B30: 2026 | C30: mix-short | E30: 1.408 | G30: 1.408 | H30: 1.904 | I30: 3.403 | L30: minute-weighted mean over the call-length mix
A31: C6 | B31: 2026 | C31: mix-companion | E31: 1.539 | G31: 1.539 | H31: 2.014 | I31: 11.523 | L31: minute-weighted mean over the call-length mix
A32: C6g | B32: 2026 | C32: 1 | D32: 0.894 | E32: 1.045 | F32: 1.193 | G32: 1.045 | H32: 1.617 | I32: 1.045 | J32: 0 | K32: 0
A33: C6g | B33: 2026 | C33: 3 | D33: 0.91 | E33: 1.066 | F33: 1.218 | G33: 1.065 | H33: 1.565 | I33: 3.197 | J33: 0 | K33: 0.001
A34: C6g | B34: 2026 | C34: 5 | D34: 0.926 | E34: 1.086 | F34: 1.243 | G34: 1.085 | H34: 1.571 | I34: 5.429 | J34: 0 | K34: 0.002
A35: C6g | B35: 2026 | C35: 10 | D35: 0.964 | E35: 1.135 | F35: 1.307 | G35: 1.135 | H35: 1.609 | I35: 11.354 | J35: 0 | K35: 0.001
A36: C6g | B36: 2026 | C36: mix-short | E36: 1.09 | G36: 1.09 | H36: 1.586 | I36: 2.658 | L36: minute-weighted mean over the call-length mix
A37: C6g | B37: 2026 | C37: mix-companion | E37: 1.169 | G37: 1.169 | H37: 1.643 | I37: 8.881 | L37: minute-weighted mean over the call-length mix
A38: C6g-HD | B38: 2026 | C38: 1 | D38: 1.335 | E38: 1.585 | F38: 1.845 | G38: 1.588 | H38: 2.158 | I38: 1.585 | J38: 0 | K38: 0
A39: C6g-HD | B39: 2026 | C39: 3 | D39: 1.352 | E39: 1.605 | F39: 1.867 | G39: 1.608 | H39: 2.106 | I39: 4.815 | J39: 0 | K39: 0
A40: C6g-HD | B40: 2026 | C40: 5 | D40: 1.37 | E40: 1.626 | F40: 1.89 | G40: 1.628 | H40: 2.111 | I40: 8.13 | J40: 0 | K40: 0
...

Sheet Volume
A1: minutes_per_month | B1: C6g_payg | C1: C6g_with_azure_tts_commit | D1: azure_gated_stt_commit_oss_neural_commit | E1: inworld_allin_growth_credits | F1: selfhost_e2e_fleet_floor
A2: 25000 | B2: 0.941 | C2: 0.954 | D2: 1.323 | E2: 0.872 | F2: 25.245
A3: 50000 | B3: 0.941 | C3: 0.954 | D3: 1.323 | E3: 0.872 | F3: 12.745
A4: 100000 | B4: 0.941 | C4: 0.954 | D4: 1.323 | E4: 0.872 | F4: 6.496
A5: 250000 | B5: 0.941 | C5: 0.954 | D5: 1.18 | E5: 0.57 | F5: 2.746
A6: 500000 | B6: 0.941 | C6: 0.954 | D6: 1.173 | E6: 0.525 | F6: 1.496
A7: 1000000 | B7: 0.941 | C7: 0.954 | D7: 1.173 | E7: 0.525 | F7: 0.871
A8: 2500000 | B8: 0.941 | C8: 0.834 | D8: 0.94 | E8: 0.525 | F8: 0.514
A9: 5000000 | B9: 0.941 | C9: 0.834 | D9: 0.927 | E9: 0.525 | F9: 0.432
A10: 10000000 | B10: 0.941 | C10: 0.782 | D10: 0.776 | E10: 0.525 | F10: 0.432

Sheet Sensitivity
A1: stack | B1: input | C1: low | D1: high | E1: ai_at_low | F1: ai_at_high | G1: ai_at_reference
A2: C6g | B2: e | C2: 3 | D2: 7 | E2: 0.785 | F2: 1.107 | G2: 0.941
A3: C6g-HD | B3: e | C3: 3 | D3: 7 | E3: 1.316 | F3: 1.638 | G3: 1.473
A4: C1 | B4: e | C4: 3 | D4: 7 | E4: 2.072 | F4: 2.316 | G4: 2.187
A5: L38 | B5: e | C5: 3 | D5: 7 | E5: 3.561 | F5: 7.41 | G5: 5.713
A6: C6g | B6: agent_s | C6: 15 | D6: 40 | E6: 0.817 | F6: 1.162 | G6: 0.941
A7: C6g-HD | B7: agent_s | C7: 15 | D7: 40 | E7: 1.15 | F7: 2.047 | G7: 1.473
A8: C1 | B8: agent_s | C8: 15 | D8: 40 | E8: 2.059 | F8: 2.416 | G8: 2.187
A9: L38 | B9: agent_s | C9: 15 | D9: 40 | E9: 4.756 | F9: 7.416 | G9: 5.713
A10: C6g | B10: caller_s | C10: 12 | D10: 32 | E10: 0.823 | F10: 1.02 | G10: 0.941
A11: C6g-HD | B11: caller_s | C11: 12 | D11: 32 | E11: 1.354 | F11: 1.552 | G11: 1.473
A12: C1 | B12: caller_s | C12: 12 | D12: 32 | E12: 2.187 | F12: 2.187 | G12: 2.187
A13: L38 | B13: caller_s | C13: 12 | D13: 32 | E13: 4.813 | F13: 6.313 | G13: 5.713
... A20: C6g | B20: groq_cache | C20: 0.75 | D20: 0.9 | E20: 0.959 | F20: 0.933 | G20: 0.941
A21: C6g | B21: s_extra_tokens (persona+memory above the lanes' harness prompt) | C21: 0 | E21: 0.941 | G21: 0.941
A22: L38 | B22: s_extra_tokens (persona+memory above the lanes' harness prompt) | C22: 0 | E22: 5.713 | G22: 5.713
A23: L31 | B23: s_extra_tokens (persona+memory above the lanes' harness prompt) | C23: 0 | E23: 4.146 | G23: 4.146
A24: C6g | B24: s_extra_tokens (persona+memory above the lanes' harness prompt) | C24: 2000 | E24: 1.127 | G24: 0.941
A25: L38 | B25: s_extra_tokens (persona+memory above the lanes' harness prompt) | C25: 2000 | E25: 6.616 | G25: 5.713
A26: L31 | B26: s_extra_tokens (persona+memory above the lanes' harness prompt) | C26: 2000 | E26: 4.763 | G26: 4.146
A27: C6g | B27: s_extra_tokens (persona+memory above the lanes' harness prompt) | C27: 4000 | E27: 1.313 | G27: 0.941
A28: L38 | B28: s_extra_tokens (persona+memory above the lanes' harness prompt) | C28: 4000 | E28: 7.518 | G28: 5.713
A29: L31 | B29: s_extra_tokens (persona+memory above the lanes' harness prompt) | C29: 4000 | E29: 5.381 | G29: 4.146
A30: C6g | B30: s_extra_tokens (persona+memory above the lanes' harness prompt) | C30: 8000 | E30: 1.685 | G30: 0.941
A31: L38 | B31: s_extra_tokens (persona+memory above the lanes' harness prompt) | C31: 8000 | E31: 9.323 | G31: 5.713
A32: L31 | B32: s_extra_tokens (persona+memory above the lanes' harness prompt) | C32: 8000 | E32: 6.616 | G32: 4.146
... A35: L31 | B35: s_extra_tokens (persona+memory above the lanes' harness prompt) | C35: 13000 | E35: 8.16 | G35: 4.146

Sheet Latency
A1: stack | B1: vantage | C1: p50_ms | D1: p50_ci95 | E1: p90_ms | F1: n | G1: cutins | H1: source
A2: C1 Azure STT + gpt-4.1-mini + Azure neural | B2: Central India VM, no phone leg | C2: 1026 | D2: 1,017-1,035 | E2: 1143 | F2: 58 (6) | G2: 16/60 main (27%); 12/12 pause | H2: g3 results/rederived_latency.csv
A3: C1g C1 + VAD-gated STT | B3: Central India VM | C3: 989 | D3: 967-994 | E3: 1072 | F3: 28 (3) | G3: 9/30; 6/6 pause | H3: g3 rederived_latency.csv
A4: C2 Azure STT + gpt-4.1-mini + DragonHD | B4: Central India VM | C4: 1133 | D4: 1,118-1,140 | E4: 1231 | F4: 58 (6) | G4: 9/60 (15%); 12/12 | H4: g3 rederived_latency.csv
A5: C3 Azure STT + gpt-oss-120b@Groq + DragonHD | B5: Central India VM | C5: 1044 | D5: 1,029-1,077 | E5: 1230 | F5: 57 (6) | G5: 16/60 (27%); 12/12 | H5: g3 rederived_latency.csv
A6: C6 transcribe-live + gpt-oss@Groq + Azure neural | B6: Central India VM | C6: 1031 | D6: 1,010-1,052 | E6: 1404 | F6: 60 (6) | G6: 19/60 (32%); 12/12 | H6: g3 rederived_latency.csv
A7: C6g C6 + VAD-gated STT | B7: Central India VM | C7: 1038 | D7: 990-1,163 | E7: 1453 | F7: 30 (3) | G7: 7/30 (23%); 6/6 | H7: g3 rederived_latency.csv
A8: C7 Azure STT + gemini-3.5-flash-lite (free) + neural | B8: Central India VM | C8: 1568 | D8: 1,514-1,602 | E8: 1790 | F8: 56 (6) | G8: 2/60; 12/12 | H8: g3 rederived_latency.csv
A9: C8 transcribe-live + flash-lite (free) + neural | B9: Central India VM | C9: 1688 | D9: 1,654-1,718 | E9: 1789 | F9: 59 (6) | G9: 2/60; 12/12 | H9: g3 rederived_latency.csv
A10: G-D Azure STT + gpt-oss + 3.8-flash-lite-tts (computed) | B10: Central India VM components | C10: 1842 | D10: 1,782-1,901 | E10: 2180 | F10: 57 x 40 TTS | G10: n/a | H10: g3 composite_gemini_tts_latency.csv
A11: G-A all-Gemini lite (computed) | B11: Central India VM components | C11: 2532 | D11: 2,498-2,566 | E11: 2722 | F11: 59 x 40 | G11: n/a | H11: g3 composite_gemini_tts_latency.csv
A12: Round-2 config A (Azure STT 500 ms + gpt-4.1-mini + neural, say-first) | B12: Central India VM | C12: 1004 | D12: 989-1,017 | E12: 1105 | F12: 48 clean | G12: 18-50% by config; 12/12 | H12: 2026-10-17 SYNTHESIS-v2 section 5 [LAT-02]
A13: Gemini 3.8 Live, paid key, Meera VAD | B13: Central India VM | C13: 1006 | D13: 950-1,253 | E13: 1524 | F13: 30 (6) | G13: 22/53 talk-over (42%); 8/8 pause | H13: g5 results/latency_summary.csv
... A21: TTS gemini-3.8-flash-lite-tts stream (paid), first byte | B21: Central India VM | C21: 857 | D21: - | E21: 997 | F21: 40 requests | G21: +0.14-0.36 s leading silence | H21: g5 tts_summary.csv
A22: TTS Azure neural Swara, first byte | B22: Central India VM | C22: 113 | D22: - | E22: 162 | F22: 24 | G22: - | H22: g3 results/tts_india_az.csv
A23: LLM gpt-oss-120b@Groq via OpenRouter, TTFT | B23: Central India VM | C23: 253 | D23: - | E23: 490 | F23: 30 | G23: - | H23: g3 results/llm_india_summary.csv
A24: LLM gpt-4.1-mini South India, TTFT | B24: Central India VM | C24: 526 | D24: - | E24: 636 | F24: 30 | G24: - | H24: g3 results/llm_india_summary.csv
A25: LLM gemini-3.5-flash-lite free tier, TTFT | B25: Central India VM | C25: 783 | D25: - | E25: 980 | F25: 30 | G25: - | H25: g3 results/llm_india_summary.csv

Sheet Calibration
A1: tag | B1: model | C1: compression | D1: call_min | E1: invocations_per_min | F1: agent_s_per_min | G1: caller_s_per_min | H1: measured_inr_min | I1: model_inr_min | J1: model_vs_measured
A2: cost_g31_10m_off_a | B2: 3.1 | C2: off | D2: 9.985 | E2: 3.91 | F2: 31.664 | G2: 13.491 | H2: 9.955 | I2: 9.223 | J2: -0.074
A3: cost_g31_10m_off_b | B3: 3.1 | C3: off | D3: 9.956 | E3: 4.62 | F3: 30.954 | G3: 13.875 | H3: 11.543 | I3: 10.624 | J3: -0.08
A4: cost_g31_10m_on2k5_a | B4: 3.1 | C4: on:2500:1500 | D4: 9.933 | E4: 4.23 | F4: 33.782 | G4: 12.167 | H4: 2.852 | I4: 3.793 | J4: 0.33
A5: cost_g31_10m_on6k_a | B5: 3.1 | C5: on:6000:3000 | D5: 10.048 | E5: 4.38 | F5: 33.969 | G5: 12.58 | H5: 6.622 | I5: 7.299 | J5: 0.102
A6: cost_g31_10m_on6k_b | B6: 3.1 | C6: on:6000:3000 | D6: 9.997 | E6: 4.1 | F6: 30.13 | G6: 13.475 | H6: 6.154 | I6: 6.778 | J6: 0.101
A7: cost_g31_1m_off_a | B7: 3.1 | C7: off | D7: 1.068 | E7: 3.74 | F7: 38.891 | G7: 10.186 | H7: 2.469 | I7: 2.642 | J7: 0.07
A8: cost_g31_1m_on6k_a | B8: 3.1 | C8: on:6000:3000 | D8: 1.304 | E8: 3.83 | F8: 34.461 | G8: 14.336 | H8: 2.553 | I8: 2.73 | J8: 0.069
A9: cost_g31_3m_off_a | B9: 3.1 | C9: off | D9: 3.035 | E9: 4.94 | F9: 34.434 | G9: 13.103 | H9: 5.079 | I9: 4.927 | J9: -0.03
A10: cost_g31_3m_off_b | B10: 3.1 | C10: off | D10: 3.044 | E10: 3.94 | F10: 35.866 | G10: 11.243 | H10: 4.326 | I10: 4.182 | J10: -0.033
A11: cost_g31_3m_on6k_a | B11: 3.1 | C11: on:6000:3000 | D11: 2.961 | E11: 3.71 | F11: 34.263 | G11: 11.556 | H11: 4.241 | I11: 3.839 | J11: -0.095
A12: cost_g31_3m_on6k_b | B12: 3.1 | C12: on:6000:3000 | D12: 3.013 | E12: 3.98 | F12: 31.236 | G12: 13.195 | H12: 4.145 | I12: 3.917 | J12: -0.055
A13: cost_g31_5m_off_a | B13: 3.1 | C13: off | D13: 4.996 | E13: 4.4 | F13: 33.404 | G13: 12.702 | H13: 6.849 | I13: 6.126 | J13: -0.106
... A27: cost_g38_5m_on6k_a | B27: 3.8 | C27: on:6000:3000 | D27: 5.018 | E27: 6.18 | F27: 28.625 | G27: 16.767 | H27: 7.94 | I27: 7.807 | J27: -0.017

Sheet Deterministic
A1: stack | B1: name | C1: evidence | D1: price_regime | E1: call_min | F1: stt_inr_min | G1: llm_or_s2s_inr_min | H1: tts_inr_min | I1: ai_inr_min | J1: ai_inr_call | K1: telephony_inr_min | L1: infra_inr_min | M1: cogs_inr_min | N1: cogs_inr_call | O1: price_ex_gst_at_40 | P1: price_ex_gst_at_50 | Q1: price_ex_gst_at_60 | R1: margin_at_inr2_ex_gst | S1: margin_at_inr2_gst_incl | T1: latency_india_p50_p90_ms | U1: cutins
A2: C1 | B2: Azure STT + gpt-4.1-mini (South India) + Azure neural | C2: measured end-to-end (g3) | D2: 2026 | E2: 1 | F2: 1.583 | G2: 0.232 | H2: 0.343 | I2: 2.158 | J2: 2.158 | K2: 0.537 | L2: 0.03 | M2: 2.726 | N2: 2.726 | O2: 4.543 | P2: 5.451 | Q2: 6.814 | R2: -0.363 | S2: -0.608 | T2: 1,026 / 1,143 | U2: 27% main, 12/12 pause
A3: C1 | B3: Azure STT + gpt-4.1-mini (South India) + Azure neural | C3: measured end-to-end (g3) | D3: 2026 | E3: 3 | F3: 1.583 | G3: 0.261 | H3: 0.343 | I3: 2.187 | J3: 6.562 | K3: 0.466 | L3: 0.03 | M3: 2.683 | N3: 8.049 | O3: 4.472 | P3: 5.366 | Q3: 6.708 | R3: -0.342 | S3: -0.583 | T3: 1,026 / 1,143 | U3: 27% main, 12/12 pause
A4: C1 | B4: Azure STT + gpt-4.1-mini (South India) + Azure neural | C4: measured end-to-end (g3) | D4: 2026 | E4: 5 | F4: 1.583 | G4: 0.29 | H4: 0.343 | I4: 2.216 | J4: 11.082 | K4: 0.451 | L4: 0.03 | M4: 2.698 | N4: 13.489 | O4: 4.496 | P4: 5.396 | Q4: 6.745 | R4: -0.349 | S4: -0.592 | T4: 1,026 / 1,143 | U4: 27% main, 12/12 pause
A5: C1 | B5: Azure STT + gpt-4.1-mini (South India) + Azure neural | C5: measured end-to-end (g3) | D5: 2026 | E5: 10 | F5: 1.583 | G5: 0.363 | H5: 0.343 | I5: 2.289 | J5: 22.891 | K5: 0.441 | L5: 0.03 | M5: 2.76 | N5: 27.599 | O5: 4.6 | P5: 5.52 | Q5: 6.9 | R5: -0.38 | S5: -0.628 | T5: 1,026 / 1,143 | U5: 27% main, 12/12 pause
A6: C1g | B6: C1 with VAD-gated STT | C6: measured end-to-end, 1 pass (g3) | D6: 2026 | E6: 1 | F6: 0.751 | G6: 0.232 | H6: 0.343 | I6: 1.326 | J6: 1.326 | K6: 0.537 | L6: 0.03 | M6: 1.893 | N6: 1.893 | O6: 3.156 | P6: 3.787 | Q6: 4.733 | R6: 0.053 | S6: -0.117 | T6: 989 / 1,072 | U6: 30% main, 6/6 pause
A7: C1g | B7: C1 with VAD-gated STT | C7: measured end-to-end, 1 pass (g3) | D7: 2026 | E7: 3 | F7: 0.751 | G7: 0.261 | H7: 0.343 | I7: 1.355 | J7: 4.065 | K7: 0.466 | L7: 0.03 | M7: 1.851 | N7: 5.552 | O7: 3.085 | P7: 3.702 | Q7: 4.627 | R7: 0.075 | S7: -0.092 | T7: 989 / 1,072 | U7: 30% main, 6/6 pause
A8: C1g | B8: C1 with VAD-gated STT | C8: measured end-to-end, 1 pass (g3) | D8: 2026 | E8: 5 | F8: 0.751 | G8: 0.29 | H8: 0.343 | I8: 1.384 | J8: 6.921 | K8: 0.451 | L8: 0.03 | M8: 1.866 | N8: 9.328 | O8: 3.109 | P8: 3.731 | Q8: 4.664 | R8: 0.067 | S8: -0.101 | T8: 989 / 1,072 | U8: 30% main, 6/6 pause
A9: C1g | B9: C1 with VAD-gated STT | C9: measured end-to-end, 1 pass (g3) | D9: 2026 | E9: 10 | F9: 0.751 | G9: 0.363 | H9: 0.343 | I9: 1.457 | J9: 14.569 | K9: 0.441 | L9: 0.03 | M9: 1.928 | N9: 19.277 | O9: 3.213 | P9: 3.855 | Q9: 4.819 | R9: 0.036 | S9: -0.137 | T9: 989 / 1,072 | U9: 30% main, 6/6 pause
A10: C2 | B10: Azure STT + gpt-4.1-mini + Azure DragonHD | C10: measured end-to-end (g3) | D10: 2026 | E10: 1 | F10: 1.583 | G10: 0.229 | H10: 0.862 | I10: 2.674 | J10: 2.674 | K10: 0.537 | L10: 0.03 | M10: 3.242 | N10: 3.242 | O10: 5.403 | P10: 6.483 | Q10: 8.104 | R10: -0.621 | S10: -0.913 | T10: 1,133 / 1,231 | U10: 15% main, 12/12 pause
A11: C2 | B11: Azure STT + gpt-4.1-mini + Azure DragonHD | C11: measured end-to-end (g3) | D11: 2026 | E11: 3 | F11: 1.583 | G11: 0.258 | H11: 0.862 | I11: 2.703 | J11: 8.11 | K11: 0.466 | L11: 0.03 | M11: 3.199 | N11: 9.598 | O11: 5.332 | P11: 6.398 | Q11: 7.998 | R11: -0.6 | S11: -0.888 | T11: 1,133 / 1,231 | U11: 15% main, 12/12 pause
A12: C2 | B12: Azure STT + gpt-4.1-mini + Azure DragonHD | C12: measured end-to-end (g3) | D12: 2026 | E12: 5 | F12: 1.583 | G12: 0.288 | H12: 0.862 | I12: 2.733 | J12: 13.663 | K12: 0.451 | L12: 0.03 | M12: 3.214 | N12: 16.071 | O12: 5.357 | P12: 6.428 | Q12: 8.035 | R12: -0.607 | S12: -0.896 | T12: 1,133 / 1,231 | U12: 15% main, 12/12 pause
A13: C2 | B13: Azure STT + gpt-4.1-mini + Azure DragonHD | C13: measured end-to-end (g3) | D13: 2026 | E13: 10 | F13: 1.583 | G13: 0.361 | H13: 0.862 | I13: 2.806 | J13: 28.059 | K13: 0.441 | L13: 0.03 | M13: 3.277 | N13: 32.766 | O13: 5.461 | P13: 6.553 | Q13: 8.192 | R13: -0.638 | S13: -0.933 | T13: 1,133 / 1,231 | U13: 15% main, 12/12 pause
... A77: RTM | B77: OpenAI gpt-realtime-2.1-mini (prefix caching) | C77: desk computation (g4); not measured | D77: 2026 | E77: 10 | F77: 0 | G77: 2.291 | H77: 0 | I77: 2.291 | J77: 22.91 | K77: 0.441 | L77: 0.03 | M77: 2.762 | N77: 27.617 | O77: 4.603 | P77: 5.523 | Q77: 6.904 | R77: -0.381 | S77: -0.629 | T77: not measured from India | U77: not measured
A78: L31-g5-off | B78: Gemini 3.1 Live, compression off (g5 paid meter) | C78: measured paid meter, n=1-2 calls per cell (g5 cost_per_minute_summary.csv) | D78: 2026 (no change announced) | E78: 1 | F78: 0 | G78: 2.47 | H78: 0 | I78: 2.47 | J78: 2.47 | K78: 0.537 | L78: 0.03 | M78: 3.038 | N78: 3.038 | O78: 5.062 | P78: 6.075 | Q78: 7.594 | R78: -0.519 | S78: -0.792 | T78: 1,950 / 5,299 | U78: 11% main, 26/26 pause
A79: L31-g5-off | B79: Gemini 3.1 Live, compression off (g5 paid meter) | C79: measured paid meter, n=1-2 calls per cell (g5 cost_per_minute_summary.csv) | D79: 2026 (no change announced) | E79: 3 | F79: 0 | G79: 4.71 | H79: 0 | I79: 4.71 | J79: 14.13 | K79: 0.466 | L79: 0.03 | M79: 5.206 | N79: 15.617 | O79: 8.676 | P79: 10.412 | Q79: 13.015 | R79: -1.603 | S79: -2.071 | T79: 1,950 / 5,299 | U79: 11% main, 26/26 pause
A80: L31-g5-off | B80: Gemini 3.1 Live, compression off (g5 paid meter) | C80: measured paid meter, n=1-2 calls per cell (g5 cost_per_minute_summary.csv) | D80: 2026 (no change announced) | E80: 5 | F80: 0 | G80: 6.85 | H80: 0 | I80: 6.85 | J80: 34.25 | K80: 0.451 | L80: 0.03 | M80: 7.332 | N80: 36.657 | O80: 12.219 | P80: 14.663 | Q80: 18.329 | R80: -2.666 | S80: -3.326 | T80: 1,950 / 5,299 | U80: 11% main, 26/26 pause
A81: L31-g5-off | B81: Gemini 3.1 Live, compression off (g5 paid meter) | C81: measured paid meter, n=1-2 calls per cell (g5 cost_per_minute_summary.csv) | D81: 2026 (no change announced) | E81: 10 | F81: 0 | G81: 10.74 | H81: 0 | I81: 10.74 | J81: 107.4 | K81: 0.441 | L81: 0.03 | M81: 11.211 | N81: 112.107 | O81: 18.685 | P81: 22.421 | Q81: 28.027 | R81: -4.605 | S81: -5.614 | T81: 1,950 / 5,299 | U81: 11% main, 26/26 pause
A82: L31-g5-on6k | B82: Gemini 3.1 Live, compression on6k (g5 paid meter) | C82: measured paid meter, n=1-2 calls per cell (g5 cost_per_minute_summary.csv) | D82: 2026 (no change announced) | E82: 1 | F82: 0 | G82: 2.55 | H82: 0 | I82: 2.55 | J82: 2.55 | K82: 0.537 | L82: 0.03 | M82: 3.117 | N82: 3.117 | O82: 5.196 | P82: 6.235 | Q82: 7.794 | R82: -0.559 | S82: -0.839 | T82: 1,950 / 5,299 | U82: 11% main, 26/26 pause
A83: L31-g5-on6k | B83: Gemini 3.1 Live, compression on6k (g5 paid meter) | C83: measured paid meter, n=1-2 calls per cell (g5 cost_per_minute_summary.csv) | D83: 2026 (no change announced) | E83: 3 | F83: 0 | G83: 4.19 | H83: 0 | I83: 4.19 | J83: 12.57 | K83: 0.466 | L83: 0.03 | M83: 4.686 | N83: 14.058 | O83: 7.81 | P83: 9.372 | Q83: 11.715 | R83: -1.343 | S83: -1.765 | T83: 1,950 / 5,299 | U83: 11% main, 26/26 pause
A84: L31-g5-on6k | B84: Gemini 3.1 Live, compression on6k (g5 paid meter) | C84: measured paid meter, n=1-2 calls per cell (g5 cost_per_minute_summary.csv) | D84: 2026 (no change announced) | E84: 5 | F84: 0 | G84: 5.34 | H84: 0 | I84: 5.34 | J84: 26.7 | K84: 0.451 | L84: 0.03 | M84: 5.822 | N84: 29.108 | O84: 9.703 | P84: 11.643 | Q84: 14.554 | R84: -1.911 | S84: -2.435 | T84: 1,950 / 5,299 | U84: 11% main, 26/26 pause
A85: L31-g5-on6k | B85: Gemini 3.1 Live, compression on6k (g5 paid meter) | C85: measured paid meter, n=1-2 calls per cell (g5 cost_per_minute_summary.csv) | D85: 2026 (no change announced) | E85: 10 | F85: 0 | G85: 6.38 | H85: 0 | I85: 6.38 | J85: 63.8 | K85: 0.441 | L85: 0.03 | M85: 6.851 | N85: 68.508 | O85: 11.418 | P85: 13.702 | Q85: 17.127 | R85: -2.425 | S85: -3.042 | T85: 1,950 / 5,299 | U85: 11% main, 26/26 pause
A86: L38-g5-off | B86: Gemini 3.8 Live, compression off (g5 paid meter) | C86: measured paid meter, n=1-2 calls per cell (g5 cost_per_minute_summary.csv) | D86: 2026 (no change announced) | E86: 1 | F86: 0 | G86: 3.31 | H86: 0 | I86: 3.31 | J86: 3.31 | K86: 0.537 | L86: 0.03 | M86: 3.877 | N86: 3.877 | O86: 6.463 | P86: 7.755 | Q86: 9.694 | R86: -0.939 | S86: -1.288 | T86: 1,006 / 1,524 | U86: 42% talk-over, 8/8 pause
A87: L38-g5-off | B87: Gemini 3.8 Live, compression off (g5 paid meter) | C87: measured paid meter, n=1-2 calls per cell (g5 cost_per_minute_summary.csv) | D87: 2026 (no change announced) | E87: 3 | F87: 0 | G87: 5.72 | H87: 0 | I87: 5.72 | J87: 17.16 | K87: 0.466 | L87: 0.03 | M87: 6.216 | N87: 18.648 | O87: 10.36 | P87: 12.432 | Q87: 15.54 | R87: -2.108 | S87: -2.667 | T87: 1,006 / 1,524 | U87: 42% talk-over, 8/8 pause
A88: L38-g5-off | B88: Gemini 3.8 Live, compression off (g5 paid meter) | C88: measured paid meter, n=1-2 calls per cell (g5 cost_per_minute_summary.csv) | D88: 2026 (no change announced) | E88: 5 | F88: 0 | G88: 8.05 | H88: 0 | I88: 8.05 | J88: 40.25 | K88: 0.451 | L88: 0.03 | M88: 8.531 | N88: 42.657 | O88: 14.219 | P88: 17.063 | Q88: 21.329 | R88: -3.266 | S88: -4.034 | T88: 1,006 / 1,524 | U88: 42% talk-over, 8/8 pause
A89: L38-g5-off | B89: Gemini 3.8 Live, compression off (g5 paid meter) | C89: measured paid meter, n=1-2 calls per cell (g5 cost_per_minute_summary.csv) | D89: 2026 (no change announced) | E89: 10 | F89: 0 | G89: 12.7 | H89: 0 | I89: 12.7 | J89: 127 | K89: 0.441 | L89: 0.03 | M89: 13.171 | N89: 131.707 | O89: 21.951 | P89: 26.341 | Q89: 32.927 | R89: -5.585 | S89: -6.771 | T89: 1,006 / 1,524 | U89: 42% talk-over, 8/8 pause
... A93: L38-g5-on6k | B93: Gemini 3.8 Live, compression on6k (g5 paid meter) | C93: measured paid meter, n=1-2 calls per cell (g5 cost_per_minute_summary.csv) | D93: 2026 (no change announced) | E93: 10 | F93: 0 | G93: 9.05 | H93: 0 | I93: 9.05 | J93: 90.5 | K93: 0.441 | L93: 0.03 | M93: 9.521 | N93: 95.207 | O93: 15.868 | P93: 19.041 | Q93: 23.802 | R93: -3.76 | S93: -4.617 | T93: 1,006 / 1,524 | U93: 42% talk-over, 8/8 pause

Sheet Budget_values
A1: price_inr_min | B1: gst_treatment | C1: net_revenue | D1: gross_margin | E1: telephony_inr_min | F1: telephony_note | G1: infra_inr_min | H1: allowed_ai_inr_min
A2: 2 | B2: ex-GST (GST added on top) | C2: 2 | D2: 0.4 | E2: 0.38 | F2: brief range 0.38-0.48 | G2: 0 | H2: 0.82
A3: 2 | B3: ex-GST (GST added on top) | C3: 2 | D3: 0.4 | E3: 0.38 | F3: brief range 0.38-0.48 | G3: 0.03 | H3: 0.79
A4: 2 | B4: ex-GST (GST added on top) | C4: 2 | D4: 0.4 | E4: 0.43 | F4: brief range 0.38-0.48 | G4: 0 | H4: 0.77
A5: 2 | B5: ex-GST (GST added on top) | C5: 2 | D5: 0.4 | E5: 0.43 | F5: brief range 0.38-0.48 | G5: 0.03 | H5: 0.74
A6: 2 | B6: ex-GST (GST added on top) | C6: 2 | D6: 0.4 | E6: 0.48 | F6: brief range 0.38-0.48 | G6: 0 | H6: 0.72
A7: 2 | B7: ex-GST (GST added on top) | C7: 2 | D7: 0.4 | E7: 0.48 | F7: brief range 0.38-0.48 | G7: 0.03 | H7: 0.69
A8: 2 | B8: ex-GST (GST added on top) | C8: 2 | D8: 0.4 | E8: 0.6 | F8: 1600-series sensitivity (no published price) | G8: 0 | H8: 0.6
A9: 2 | B9: ex-GST (GST added on top) | C9: 2 | D9: 0.4 | E9: 0.6 | F9: 1600-series sensitivity (no published price) | G9: 0.03 | H9: 0.57
A10: 2 | B10: ex-GST (GST added on top) | C10: 2 | D10: 0.4 | E10: 0.8 | F10: 1600-series sensitivity (no published price) | G10: 0 | H10: 0.4
A11: 2 | B11: ex-GST (GST added on top) | C11: 2 | D11: 0.4 | E11: 0.8 | F11: 1600-series sensitivity (no published price) | G11: 0.03 | H11: 0.37
A12: 2 | B12: ex-GST (GST added on top) | C12: 2 | D12: 0.5 | E12: 0.38 | F12: brief range 0.38-0.48 | G12: 0 | H12: 0.62
A13: 2 | B13: ex-GST (GST added on top) | C13: 2 | D13: 0.5 | E13: 0.38 | F13: brief range 0.38-0.48 | G13: 0.03 | H13: 0.59
... A61: 2 | B61: GST-inclusive (18% inside) | C61: 1.695 | D61: 0.6 | E61: 0.8 | F61: 1600-series sensitivity (no published price) | G61: 0.03 | H61: -0.152

Sheet Tiers_by_length
A1: tier | B1: call_min | C1: price_inr_min_ex_gst | D1: price_inr_call_ex_gst | E1: price_inr_min_incl_gst | F1: stt | G1: llm | H1: tts | I1: learn | J1: ai_inr_min | K1: telephony | L1: infra | M1: cogs_inr_min | N1: cogs_inr_call | O1: gross_margin | P1: margin_if_telephony_passed_through | Q1: margin_if_1600_telephony_0_60 | R1: margin_if_1600_telephony_0_80 | S1: voice_fee_inr_month
A2: base | B2: 1 | C2: 2.99 | D2: 2.99 | E2: 3.528 | F2: 0.382 | G2: 0.303 | H2: 0.33 | I2: 0 | J2: 1.015 | K2: 0.537 | L2: 0.03 | M2: 1.583 | N2: 1.583 | O2: 0.471 | P2: 0.65 | Q2: 0.4 | R2: 0.316 | S2: 0
A3: base | B3: 3 | C3: 2.99 | D3: 8.97 | E3: 3.528 | F3: 0.382 | G3: 0.322 | H3: 0.33 | I3: 0 | J3: 1.034 | K3: 0.466 | L3: 0.03 | M3: 1.53 | N3: 4.59 | O3: 0.488 | P3: 0.644 | Q3: 0.427 | R3: 0.354 | S3: 0
A4: base | B4: 5 | C4: 2.99 | D4: 14.95 | E4: 3.528 | F4: 0.382 | G4: 0.34 | H4: 0.33 | I4: 0 | J4: 1.053 | K4: 0.451 | L4: 0.03 | M4: 1.534 | N4: 7.672 | O4: 0.487 | P4: 0.638 | Q4: 0.427 | R4: 0.357 | S4: 0
A5: base | B5: 10 | C5: 2.99 | D5: 29.9 | E5: 3.528 | F5: 0.382 | G5: 0.387 | H5: 0.33 | I5: 0 | J5: 1.1 | K5: 0.441 | L5: 0.03 | M5: 1.57 | N5: 15.705 | O5: 0.475 | P5: 0.622 | Q5: 0.416 | R5: 0.348 | S5: 0
A6: base-HD | B6: 1 | C6: 3.49 | D6: 3.49 | E6: 4.118 | F6: 0.382 | G6: 0.303 | H6: 0.862 | I6: 0 | J6: 1.547 | K6: 0.537 | L6: 0.03 | M6: 2.114 | N6: 2.114 | O6: 0.394 | P6: 0.548 | Q6: 0.333 | R6: 0.262 | S6: 0
A7: base-HD | B7: 3 | C7: 3.49 | D7: 10.47 | E7: 4.118 | F7: 0.382 | G7: 0.322 | H7: 0.862 | I7: 0 | J7: 1.566 | K7: 0.466 | L7: 0.03 | M7: 2.061 | N7: 6.184 | O7: 0.409 | P7: 0.543 | Q7: 0.357 | R7: 0.294 | S7: 0
A8: base-HD | B8: 5 | C8: 3.49 | D8: 17.45 | E8: 4.118 | F8: 0.382 | G8: 0.34 | H8: 0.862 | I8: 0 | J8: 1.584 | K8: 0.451 | L8: 0.03 | M8: 2.066 | N8: 10.329 | O8: 0.408 | P8: 0.537 | Q8: 0.357 | R8: 0.297 | S8: 0
A9: base-HD | B9: 10 | C9: 3.49 | D9: 34.9 | E9: 4.118 | F9: 0.382 | G9: 0.387 | H9: 0.862 | I9: 0 | J9: 1.631 | K9: 0.441 | L9: 0.03 | M9: 2.102 | N9: 21.019 | O9: 0.398 | P9: 0.524 | Q9: 0.348 | R9: 0.289 | S9: 0
A10: plus | B10: 1 | C10: 3.99 | D10: 3.99 | E10: 4.708 | F10: 0.382 | G10: 0.582 | H10: 0.33 | I10: 0.285 | J10: 1.579 | K10: 0.537 | L10: 0.03 | M10: 2.147 | N10: 2.147 | O10: 0.462 | P10: 0.597 | Q10: 0.409 | R10: 0.346 | S10: 0
A11: plus | B11: 3 | C11: 3.99 | D11: 11.97 | E11: 4.708 | F11: 0.382 | G11: 0.6 | H11: 0.33 | I11: 0.101 | J11: 1.414 | K11: 0.466 | L11: 0.03 | M11: 1.91 | N11: 5.729 | O11: 0.521 | P11: 0.638 | Q11: 0.475 | R11: 0.421 | S11: 0
A12: plus | B12: 5 | C12: 3.99 | D12: 19.95 | E12: 4.708 | F12: 0.382 | G12: 0.619 | H12: 0.33 | I12: 0.064 | J12: 1.396 | K12: 0.451 | L12: 0.03 | M12: 1.877 | N12: 9.386 | O12: 0.529 | P12: 0.643 | Q12: 0.485 | R12: 0.432 | S12: 0
A13: plus | B13: 10 | C13: 3.99 | D13: 39.9 | E13: 4.708 | F13: 0.382 | G13: 0.666 | H13: 0.33 | I13: 0.037 | J13: 1.415 | K13: 0.441 | L13: 0.03 | M13: 1.886 | N13: 18.858 | O13: 0.527 | P13: 0.638 | Q13: 0.484 | R13: 0.432 | S13: 0
... A17: premium | B17: 10 | C17: 6.49 | D17: 64.9 | E17: 7.658 | F17: 0.751 | G17: 1.498 | H17: 0.549 | I17: 0.062 | J17: 2.86 | K17: 0.441 | L17: 0.03 | M17: 3.331 | N17: 33.308 | O17: 0.487 | P17: 0.555 | Q17: 0.46 | R17: 0.428 | S17: 350000
